Workbook

Sheet Wikia | Gehege
A1: GEHEGE
A2: Tierart | B2: Gefähr-dungs-level | C2: DLC | D2: Kontinent(e) | J2: Biom(e) | Q2: Minimale Gehegevoraussetzungen (Fläche für 1 Tier) | V2: Zaunanforderungen | Z2: Sozialverhalten | AF2: Lebenserwartung | AH2: Lebenszyklus
D4: Afrika | E4: Asien | F4: Europa | G4: Nord-amerika | H4: Ozeanien | I4: Süd-/Mittel-amerika | J4: Aquatisch | K4: Gemäßigt | L4: Grasland-schaft | M4: Taiga | N4: Tropen | O4: Tundra | P4: Wüste | Q4: Gehege-größe | R4: Kletter-fläche | S4: Wasser-fläche | T4: Tiefwasser-fläche | U4: Temperatur | V4: Kletter-schutz | W4: Zaun-stärke | X4: Zaun- höhe | Y4: Wasser-graben als Zaun | Z4: Gemischt MIN | AA4: Gemischt MAX | AB4: Gemischt Verhältnis | AC4: Nur ♂ | AD4: Nur ♀ | AE4: Gehege begehbar? | AF4: ♂ | AG4: ♀ | AH4: Geschlechts- reife | AI4: Sterilität | AJ4: Nachwuchs pro Paarung | AK4: Tragezeit | AL4: Zeitraum zwichen Geburten
A5: Afrikanischer Leopard | B5: G | C5: 0 | D5: X | L5: X | N5: X | Q5: 705 | R5: 45 | S5: 0 | T5: 0 | U5: 13-42 | V5: Ja | W5: 3 | X5: 3 | Y5: Nein | Z5: 1 | AA5: 2 | AB5: 1 ♂ / 1 ♀ | AC5: 1 | AD5: 1 | AE5: Nein | AF5: 15 | AG5: 15 | AH5: 2.5 | AI5: 15 | AJ5: 2-3 | AK5: 3 | AL5: 32
A6: Afrikanischer Steppenelefant | B6: SG | C6: 0 | D6: X | J6: X | L6: X | P6: X | Q6: 2151 | R6: 0 | S6: 148 | T6: 0 | U6: 8-44 | V6: Nein | W6: 4 | X6: 2 | Y6: Nein | Z6: 3 | AA6: 15 | AB6: 1 ♂ / 14 ♀ | AC6: 3-5 | AD6: 3-15 | AE6: Nein | AF6: 65 | AG6: 65 | AH6: 15 | AI6: Tod | AJ6: 1 | AK6: 22 | AL6: 108
A7: Afrikanischer Strauß | B7: NG | C7: 0 | D7: X | L7: X | P7: X | Q7: 675 | R7: 0 | S7: 0 | T7: 0 | U7: 8-40 | V7: Nein | W7: 2 | X7: 1.25 | Y7: Nein | Z7: 1 | AA7: 8 | AB7: 1 ♂ / 7 ♀ | AC7: 1-2 | AD7: 1-2 | AE7: Nein | AF7: 46 | AG7: 46 | AH7: 3 | AI7: Tod | AJ7: 1-5 | AK7: 1 | AL7: 12
A8: Afrikanischer Wildhund | B8: SG | C8: 0 | D8: X | L8: X | P8: X | Q8: 1162 | R8: 0 | S8: 0 | T8: 0 | U8: 8-40 | V8: Nein | W8: 2 | X8: 1.25 | Y8: Nein | Z8: 2 | AA8: 27 | AB8: 27 ♂ / 9 ♀ | AC8: 2-27 | AD8: 2-27 | AE8: Nein | AF8: 11 | AG8: 11 | AH8: 2 | AI8: 10 | AJ8: 1-6 | AK8: 2 | AL8: 14
A9: Aldabra-Riesenschildkröte | B9: G | C9: 0 | D9: X | N9: X | Q9: 230 | R9: 0 | S9: 0 | T9: 0 | U9: 16-42 | V9: Nein | W9: 1 | X9: 0.5 | Y9: Nein | Z9: 1 | AA9: 4 | AB9: 1 ♂ / 3 ♀ | AC9: 1-2 | AD9: 1-4 | AE9: Ja | AF9: 119 | AG9: 119 | AH9: 25 | AI9: Tod | AJ9: 2-8 | AK9: 8 | AL9: 24
A10: Alpaka | B10: Z | C10: 18 | I10: X | K10: X | L10: X | M10: X | Q10: 325 | R10: 0 | S10: 0 | T10: 0 | U10: -8-38 | V10: Nein | W10: 2 | X10: 1.25 | Y10: Nein | Z10: 3 | AA10: 40 | AB10: 13 ♂ / 39 ♀ | AC10: 3-40 | AD10: 3-40 | AE10: Ja+ | AF10: 20 | AG10: 20 | AH10: 3 | AI10: 18 | AJ10: 1 | AK10: 11 | AL10: 0
A11: Alpensteinbock | B11: NG | C11: 9 | F11: X | M11: X | Q11: 390 | R11: 0 | S11: 0 | T11: 0 | U11: -7-28 | V11: Nein | W11: 2 | X11: 1.25 | Y11: Nein | Z11: 2 | AA11: 20 | AB11: 1 ♂ / 19 ♀ | AC11: 2-8 | AD11: 2-20 | AE11: Nein | AF11: 21 | AG11: 21 | AH11: 2 | AI11: 15 | AJ11: 1 | AK11: 6 | AL11: 12
A12: Amerikanischer Standard-Esel | B12: Z | C12: 18 | G12: X | K12: X | L12: X | P12: X | Q12: 500 | R12: 0 | S12: 0 | T12: 0 | U12: -4-43 | V12: Nein | W12: 3 | X12: 1.25 | Y12: Nein | Z12: 1 | AA12: 6 | AB12: 1 ♂ / 5 ♀ | AC12: 1-6 | AD12: 1-6 | AE12: Ja+ | AF12: 35 | AG12: 35 | AH12: 2.5 | AI12: Tod | AJ12: 1 | AK12: 12 | AL12: 12
A13: Amerikanischer Biber | B13: NG | C13: 8 | G13: X | J13: X | K13: X | L13: X | M13: X | Q13: 480 | R13: 0 | S13: 335 | T13: 65 | U13: -7-38 | V13: Nein | W13: 2 | X13: 1.5 | Y13: Nein | Z13: 2 | AA13: 8 | AB13: 8 ♂ / 8 ♀ | AC13: 2 | AD13: 2 | AE13: Ja | AF13: 15 | AG13: 15 | AH13: 2 | AI13: Tod | AJ13: 1-5 | AK13: 2 | AL13: 12
A14: Amerikanischer Bison | B14: PG | C14: 0 | G14: X | L14: X | M14: X | Q14: 420 | R14: 0 | S14: 0 | T14: 0 | U14: -16-40 | V14: Nein | W14: 3 | X14: 1.25 | Y14: Nein | Z14: 3 | AA14: 15 | AB14: 1 ♂ / 14 ♀ | AC14: 3-15 | AD14: 3-15 | AE14: Nein | AF14: 26 | AG14: 26 | AH14: 5 | AI14: 25 | AJ14: 1 | AK14: 10 | AL14: 12
A15: Amurleopard | B15: AB | C15: 11 | E15: X | K15: X | M15: X | Q15: 705 | R15: 45 | S15: 0 | T15: 0 | U15: -15-31 | V15: Ja | W15: 3 | X15: 3 | Y15: Nein | Z15: 1 | AA15: 2 | AB15: 1 ♂ / 1 ♀ | AC15: 1 | AD15: 1 | AE15: Nein | AF15: 15 | AG15: 15 | AH15: 3 | AI15: 15 | AJ15: 1-3 | AK15: 3 | AL15: 33
A16: Bindenwaran | B16: NG | C16: 14 | E16: X | J16: X | L16: X | N16: X | Q16: 280 | R16: 0 | S16: 75 | T16: 0 | U16: 12-42 | V16: Nein | W16: 2 | X16: 1 | Y16: Nein | Z16: 1 | AA16: 2 | AB16: 1 ♂ / 1 ♀ | AC16: 1 | AD16: 1 | AE16: Nein | AF16: 18 | AG16: 18 | AH16: 3 | AI16: Tod | AJ16: 2-8 | AK16: 8 | AL16: 24
A17: Binturong | B17: G | C17: 6 | E17: X | K17: X | N17: X | Q17: 182 | R17: 40 | S17: 0 | T17: 0 | U17: 13-42 | V17: Ja | W17: 2 | X17: 3 | Y17: Nein | Z17: 2 | AA17: 5 | AB17: 5 ♂ / 5 ♀ | AC17: 2-5 | AD17: 2-5 | AE17: Ja | AF17: 22 | AG17: 22 | AH17: 1.5 | AI17: 15 | AJ17: 1-3 | AK17: 3 | AL17: 12
A18: Blauer Pfau | B18: NG | C18: 0 | E18: X | K18: X | L18: X | N18: X | Q18: 312 | R18: 0 | S18: 0 | T18: 0 | U18: 3-42 | V18: Nein | W18: 1 | X18: 1.25 | Y18: Nein | Z18: 4 | AA18: 20 | AB18: 4 ♂ / 16 ♀ | AC18: 4 | AD18: 4-16 | AE18: Ja+ | AF18: 23 | AG18: 23 | AH18: 3 | AI18: Tod | AJ18: 2-6 | AK18: 1 | AL18: 12
A19: Bongo | B19: PG | C19: 0 | D19: X | N19: X | Q19: 240 | R19: 0 | S19: 0 | T19: 0 | U19: 8-42 | V19: Nein | W19: 2 | X19: 1.25 | Y19: Nein | Z19: 1 | AA19: 5 | AB19: 1 ♂ / 4 ♀ | AC19: 1 | AD19: 1-5 | AE19: Nein | AF19: 18 | AG19: 18 | AH19: 2 | AI19: Tod | AJ19: 1 | AK19: 9 | AL19: 24
A20: Bonobo | B20: SG | C20: 0 | D20: X | N20: X | Q20: 780 | R20: 80 | S20: 0 | T20: 0 | U20: 8-42 | V20: Ja | W20: 3 | X20: 5 | Y20: 6,00 m ↔ 2,00 m ↕ | Z20: 3 | AA20: 10 | AB20: 7 ♂ / 7 ♀ | AC20: 3-10 | AD20: 3-10 | AE20: Nein | AF20: 40 | AG20: 40 | AH20: 11 | AI20: 50 | AJ20: 1 | AK20: 8 | AL20: 60
A21: Borneo-Orang-Utan | B21: AB | C21: 0 | E21: X | N21: X | Q21: 780 | R21: 120 | S21: 0 | T21: 0 | U21: 8-42 | V21: Ja | W21: 3 | X21: 5 | Y21: 6,00 m ↔ 2,00 m ↕ | Z21: 1 | AA21: 6 | AB21: 1 ♂ / 5 ♀ | AC21: 1 | AD21: 1-6 | AE21: Nein | AF21: 44 | AG21: 44 | AH21: 13 | AI21: Tod | AJ21: 1 | AK21: 8 | AL21: 96
A22: Brauen-Glattstirnkaiman | B22: NG | C22: 5 | I22: X | J22: X | K22: X | L22: X | N22: X | Q22: 182 | R22: 0 | S22: 79 | T22: 0 | U22: 6-42 | V22: Nein | W22: 2 | X22: 1.5 | Y22: Nein | Z22: 1 | AA22: 2 | AB22: 1 ♂ / 1 ♀ | AC22: 1 | AD22: 1 | AE22: Nein | AF22: 50 | AG22: 50 | AH22: 10 | AI22: Tod | AJ22: 2-7 | AK22: 3 | AL22: 12
A23: Breitmaulnashorn | B23: PG | C23: 7 | D23: X | L23: X | Q23: 1275 | R23: 0 | S23: 0 | T23: 0 | U23: 13-38 | V23: Nein | W23: 4 | X23: 2 | Y23: Nein | Z23: 1 | AA23: 5 | AB23: 1 ♂ / 4 ♀ | AC23: 1-2 | AD23: 1-5 | AE23: Nein | AF23: 43 | AG23: 43 | AH23: 5 | AI23: 46 | AJ23: 1 | AK23: 18 | AL23: 60
A24: Brillenbär | B24: G | C24: 19 | I24: X | L24: X | M24: X | N24: X | O24: X | Q24: 850 | R24: 64 | S24: 0 | T24: 0 | U24: -13-42 | V24: Ja | W24: 4 | X24: 3 | Y24: Nein | Z24: 1 | AA24: 2 | AB24: 1 ♂ / 1 ♀ | AC24: 1 | AD24: 1 | AE24: Nein | AF24: 25 | AG24: 25 | AH24: 6 | AI24: 25 | AJ24: 1-2 | AK24: 7 | AL24: 17
A25: Brillenpinguin | B25: SG | C25: 7 | D25: X | J25: X | P25: X | Q25: 180 | R25: 0 | S25: 135 | T25: 67 | U25: 3-43 | V25: Nein | W25: 2 | X25: 1.5 | Y25: Nein | Z25: 6 | AA25: 500 | AB25: 500 ♂ / 500 ♀ | AC25: 6-500 | AD25: 6-500 | AE25: Ja | AF25: 27 | AG25: 27 | AH25: 4 | AI25: 14 | AJ25: 2 | AK25: 1 | AL25: 12
A26: Capybara | B26: NG | C26: 10 | I26: X | J26: X | L26: X | N26: X | Q26: 285 | R26: 0 | S26: 70 | T26: 0 | U26: 13-42 | V26: Nein | W26: 2 | X26: 1.25 | Y26: Nein | Z26: 4 | AA26: 20 | AB26: 9 ♂ / 19 ♀ | AC26: 4-20 | AD26: 4-20 | AE26: Ja+ | AF26: 10 | AG26: 10 | AH26: 1.5 | AI26: Tod | AJ26: 2-6 | AK26: 5 | AL26: 12
A27: Chinesisches Schuppentier | B27: AB | C27: 0 | E27: X | K27: X | N27: X | Q27: 182 | R27: 0 | S27: 0 | T27: 0 | U27: 12-42 | V27: Ja | W27: 2 | X27: 2 | Y27: Nein | Z27: 1 | AA27: 3 | AB27: 3 ♂ / 3 ♀ | AC27: 1-3 | AD27: 1-3 | AE27: Ja | AF27: 13 | AG27: 13 | AH27: 1 | AI27: Tod | AJ27: 1 | AK27: 8 | AL27: 12
A28: Coquerel-Sifaka | B28: AB | C28: 19 | D28: X | N28: X | Q28: 215 | R28: 25 | S28: 0 | T28: 0 | U28: 15-42 | V28: Ja | W28: 2 | X28: 3 | Y28: Nein | Z28: 2 | AA28: 6 | AB28: 5 ♂ / 5 ♀ | AC28: 2-6 | AD28: 2-6 | AE28: Ja | AF28: 25 | AG28: 25 | AH28: 3 | AI28: 15 | AJ28: 1 | AK28: 5 | AL28: 6
A29: Dall-Schaf | B29: NG | C29: 2 | G29: X | M29: X | O29: X | Q29: 425 | R29: 0 | S29: 0 | T29: 0 | U29: -12-16 | V29: Nein | W29: 2 | X29: 1.25 | Y29: Nein | Z29: 3 | AA29: 40 | AB29: 1 ♂ / 39 ♀ | AC29: 3-15 | AD29: 3-40 | AE29: Nein | AF29: 18 | AG29: 18 | AH29: 5 | AI29: Tod | AJ29: 1-2 | AK29: 6 | AL29: 12
A30: Damagazelle | B30: AB | C30: 15 | D30: X | L30: X | P30: X | Q30: 425 | R30: 0 | S30: 0 | T30: 0 | U30: 3-43 | V30: Nein | W30: 2 | X30: 1.25 | Y30: Nein | Z30: 3 | AA30: 20 | AB30: 1 ♂ / 19 ♀ | AC30: 3-20 | AD30: 3-20 | AE30: Ja | AF30: 15 | AG30: 15 | AH30: 1.5 | AI30: Tod | AJ30: 1 | AK30: 6 | AL30: 12
A31: Damhirsch | B31: NG | C31: 9 | F31: X | K31: X | L31: X | Q31: 360 | R31: 0 | S31: 0 | T31: 0 | U31: -4-38 | V31: Nein | W31: 2 | X31: 1.25 | Y31: Nein | Z31: 3 | AA31: 16 | AB31: 1 ♂ / 15 ♀ | AC31: 3-6 | AD31: 3-15 | AE31: Ja+ | AF31: 15 | AG31: 18 | AH31: 4 | AI31: Tod | AJ31: 1-2 | AK31: 8 | AL31: 12
A32: Dingo | B32: G | C32: 4 | H32: X | K32: X | L32: X | N32: X | P32: X | Q32: 1162 | R32: 0 | S32: 0 | T32: 0 | U32: 8-43 | V32: Nein | W32: 2 | X32: 1.25 | Y32: Nein | Z32: 2 | AA32: 12 | AB32: 12 ♂ / 12 ♀ | AC32: 2-12 | AD32: 2-12 | AE32: Nein | AF32: 18 | AG32: 18 | AH32: 3 | AI32: Tod | AJ32: 1-5 | AK32: 2 | AL32: 12
A33: Dromedar-Kamel | B33: Z | C33: 15 | D33: X | E33: X | K33: X | L33: X | P33: X | Q33: 600 | R33: 0 | S33: 0 | T33: 0 | U33: -6-44 | V33: Nein | W33: 3 | X33: 1.25 | Y33: Nein | Z33: 2 | AA33: 13 | AB33: 1 ♂ / 12 ♀ | AC33: 2-9 | AD33: 2-13 | AE33: Nein | AF33: 45 | AG33: 45 | AH33: 5 | AI33: 35 | AJ33: 1 | AK33: 15 | AL33: 24
A34: Eisbär | B34: G | C34: 2 | F34: X | G34: X | J34: X | M34: X | O34: X | Q34: 3250 | R34: 0 | S34: 720 | T34: 0 | U34: -20-16 | V34: Nein | W34: 4 | X34: 2 | Y34: Nein | Z34: 1 | AA34: 2 | AB34: 1 ♂ / 1 ♀ | AC34: 1 | AD34: 1-2 | AE34: Nein | AF34: 35 | AG34: 35 | AH34: 7 | AI34: 30 | AJ34: 1-3 | AK34: 9 | AL34: 36
A35: Elch | B35: NG | C35: 8 | E35: X | F35: X | G35: X | J35: X | K35: X | M35: X | O35: X | Q35: 754 | R35: 0 | S35: 20 | T35: 0 | U35: -22-20 | V35: Nein | W35: 3 | X35: 1.25 | Y35: Nein | Z35: 1 | AA35: 4 | AB35: 1 ♂ / 3 ♀ | AC35: 1 | AD35: 1-4 | AE35: Nein | AF35: 20 | AG35: 20 | AH35: 2 | AI35: Tod | AJ35: 1 | AK35: 8 | AL35: 12
A36: Emu | B36: NG | C36: 13 | H36: X | K36: X | L36: X | N36: X | P36: X | Q36: 450 | R36: 0 | S36: 0 | T36: 0 | U36: 3-43 | V36: Nein | W36: 2 | X36: 1.25 | Y36: Nein | Z36: 1 | AA36: 6 | AB36: 5 ♂ / 5 ♀ | AC36: 1-6 | AD36: 1-6 | AE36: Nein | AF36: 15 | AG36: 15 | AH36: 1.5 | AI36: Tod | AJ36: 1-5 | AK36: 3 | AL36: 12
A37: Erdferkel | B37: NG | C37: 0 | D37: X | L37: X | N37: X | Q37: 330 | R37: 0 | S37: 0 | T37: 0 | U37: 16-42 | V37: Nein | W37: 2 | X37: 0.5 | Y37: Nein | Z37: 1 | AA37: 2 | AB37: 1 ♂ / 1 ♀ | AC37: 1-2 | AD37: 1-2 | AE37: Ja | AF37: 18 | AG37: 18 | AH37: 2 | AI37: Tod | AJ37: 1 | AK37: 7 | AL37: 24
A38: Erdmännchen | B38: NG | C38: 7 | D38: X | L38: X | P38: X | Q38: 180 | R38: 0 | S38: 0 | T38: 0 | U38: 8-43 | V38: Nein | W38: 2 | X38: 1.2 | Y38: Nein | Z38: 2 | AA38: 30 | AB38: 20 ♂ / 20 ♀ | AC38: 2-12 | AD38: 2-3 | AE38: Ja | AF38: 15 | AG38: 15 | AH38: 3 | AI38: Tod | AJ38: 3-6 | AK38: 2 | AL38: 12
A39: Eurasischer Luchs | B39: NG | C39: 9 | E39: X | F39: X | K39: X | L39: X | M39: X | O39: X | Q39: 615 | R39: 0 | S39: 0 | T39: 0 | U39: -13-38 | V39: Ja | W39: 3 | X39: 3 | Y39: Nein | Z39: 1 | AA39: 2 | AB39: 1 ♂ / 1 ♀ | AC39: 1 | AD39: 1-3 | AE39: Nein | AF39: 18 | AG39: 18 | AH39: 3 | AI39: 15 | AJ39: 1-4 | AK39: 2 | AL39: 24
A40: Europäischer Dachs | B40: NG | C40: 9 | E40: X | F40: X | K40: X | L40: X | M40: X | Q40: 360 | R40: 0 | S40: 0 | T40: 0 | U40: -7-38 | V40: Nein | W40: 2 | X40: 1 | Y40: Nein | Z40: 1 | AA40: 7 | AB40: 6 ♂ / 6 ♀ | AC40: 1-3 | AD40: 1-7 | AE40: Nein | AF40: 17 | AG40: 17 | AH40: 2 | AI40: Tod | AJ40: 1-5 | AK40: 2 | AL40: 12
A41: Fennek | B41: NG | C41: 7 | D41: X | P41: X | Q41: 182 | R41: 0 | S41: 0 | T41: 0 | U41: 3-43 | V41: Nein | W41: 2 | X41: 1.5 | Y41: Nein | Z41: 1 | AA41: 10 | AB41: 6 ♂ / 6 ♀ | AC41: 1-5 | AD41: 1-5 | AE41: Ja | AF41: 12 | AG41: 12 | AH41: 1 | AI41: 8 | AJ41: 2-5 | AK41: 1 | AL41: 12
...

Sheet Wikia | Vivarien
A1: VIVARIEN
A2: Tierart | B2: Gefähr-dungs-level | C2: DLC | D2: Kontinent(e) | J2: Biom(e) | Q2: Vivarien- anforderungen | S2: Gruppen-größe | T2: Lebenserwartung | V2: Lebenszyklus
D4: Afrika | E4: Asien | F4: Europa | G4: Nord-amerika | H4: Ozeanien | I4: Süd-/Mittel-amerika | J4: Aquat-isch | K4: Gemäß-igt | L4: Grasl-and-schaft | M4: Taiga | N4: Tropen | O4: Tundra | P4: Wüste | Q4: Temperatur | R4: Luftfeuchtig-keit | S4: Gemischt Min/Max Anzahl | T4: ♂ | U4: ♀ | V4: Geschlechts- reife | W4: Sterilität | X4: Nachwuchs pro Paarung | Y4: Tragezeit | Z4: Zeitraum zwichen Geburten
A5: Abgottschlange | B5: NG | C5: 0 | I5: X | L5: X | N5: X | Q5: 23-31 | R5: 60-80 | S5: 1-2 | T5: 30 | U5: 30 | V5: 3-4 | W5: Tod | X5: 1 | Y5: 4 | Z5: 24
A6: Australische Großschabe | B6: UD | C6: 0 | H6: X | K6: X | Q6: 25-30 | R6: 60-80 | S6: 1-6 | T6: 9 | U6: 9 | V6: 3 | W6: Tod | X6: 2-5 | Y6: 9 | Z6: 3
A7: Axolotl | B7: AB | C7: 11 | G7: X | J7: X | P7: X | Q7: 15-20 | R7: 80-90 | S7: 1-5 | T7: 8 | U7: 8 | V7: 1 | W7: Tod | X7: 2-3 | Y7: 0 | Z7: 12
A8: Blauer Morphofalter | B8: UD | C8: 13 | I8: X | L8: X | N8: X | Q8: 21-35 | R8: - | S8: 1-90 | T8: 4 | U8: 4 | V8: 3 | W8: Tod | X8: 3-6 | Y8: 0 | Z8: Nur 1 Paarung
A9: Blauzungenskink | B9: NG | C9: 4 | H9: X | K9: X | L9: X | N9: X | Q9: 25-35 | R9: 50-60 | S9: 1-2 | T9: 12 | U9: 12 | V9: 2 | W9: Tod | X9: 1-3 | Y9: 4 | Z9: 22
A10: Brasilianische Riesenvogelspinne | B10: UD | C10: 0 | I10: X | N10: X | Q10: 23-29 | R10: 50-84 | S10: 1-6 | T10: 12 | U10: 12 | V10: ♂: 2 Jahr(e) ♀: 3 Jahr(e) | W10: Tod | X10: 2-4 | Y10: 1 | Z10: 11
A11: Brasilianische Wanderspinne | B11: UD | C11: 0 | I11: X | N11: X | Q11: 23-29 | R11: 50-84 | S11: 1-6 | T11: 4 | U11: 4 | V11: 1 | W11: Tod | X11: 2-4 | Y11: 1 | Z11: 11
A12: Brasilianischer Riesenläufer | B12: UD | C12: 0 | I12: X | N12: X | Q12: 23-29 | R12: 50-84 | S12: 1-2 | T12: 10 | U12: 10 | V12: 2 | W12: Tod | X12: 1-4 | Y12: 4 | Z12: 2
A13: Braunkehl-Faultier | B13: NG | C13: 14 | I13: X | N13: X | Q13: 21-32 | R13: - | S13: 1-6 | T13: 35 | U13: 35 | V13: 4 | W13: Tod | X13: 1 | Y13: 8 | Z13: 12
A14: Brillenflughund | B14: SG | C14: 16 | H14: X | N14: X | Q14: 21-32 | R14: - | S14: 5-35 | T14: 16.5 | U14: 16.5 | V14: 3 | W14: 11 | X14: 1 | Y14: 4 | Z14: 8
A15: Diamantschildkröte | B15: G | C15: 5 | G15: X | J15: X | K15: X | Q15: 21-32 | R15: 65-80 | S15: 1-8 | T15: 35 | U15: 35 | V15: ♂: 2-3 Jahr(e) ♀: 8-10 Jahr(e) | W15: Tod | X15: 2-4 | Y15: 3 | Z15: 9
A16: Donau-Kammmolch | B16: NG | C16: 10 | F16: X | J16: X | K16: X | Q16: 12-25 | R16: 55-75 | S16: 1-6 | T16: 7.5 | U16: 7.5 | V16: 2,5 | W16: Tod | X16: 1-3 | Y16: 3 | Z16: 9
A17: Echte Achatschnecke | B17: UD | C17: 0 | D17: X | L17: X | N17: X | Q17: 23-36 | R17: 40-60 | S17: 1-6 | T17: 7 | U17: 7 | V17: 2 | W17: Tod | X17: 2-7 | Y17: 1 | Z17: 36
A18: Feuersalamander | B18: NG | C18: 9 | F18: X | K18: X | Q18: 15-24 | R18: 60-75 | S18: 1-6 | T18: 19 | U18: 19 | V18: 5 | W18: Tod | X18: 1-2 | Y18: 3 | Z18: 9
A19: Gelbe Anakonda | B19: NG | C19: 0 | I19: X | J19: X | N19: X | Q19: 25-30 | R19: 80-90 | S19: 1-2 | T19: 20 | U19: 20 | V19: 3-4 | W19: Tod | X19: 1 | Y19: 6 | Z19: 6
A20: Gila-Krustenechse | B20: PG | C20: 0 | G20: X | P20: X | Q20: 35-42 | R20: 15-25 | S20: 1-4 | T20: 25 | U20: 25 | V20: 3-5 | W20: Tod | X20: 1-2 | Y20: 9 | Z20: 3
A21: Goliathfrosch | B21: SG | C21: 0 | D21: X | J21: X | N21: X | Q21: 26-32 | R21: 74-86 | S21: 1-2 | T21: 18 | U21: 18 | V21: 10-12 | W21: Tod | X21: 1-2 | Y21: 3 | Z21: 9
A22: Goliathkäfer | B22: UD | C22: 0 | D22: X | L22: X | N22: X | Q22: 23-36 | R22: 40-60 | S22: 1-8 | T22: 2 | U22: 2 | V22: 1 | W22: Tod | X22: 3-6 | Y22: 0 | Z22: Nur 1 Paarung
A23: Griechische Landschildkröte | B23: PG | C23: 17 | F23: X | K23: X | L23: X | Q23: 25-35 | R23: 50-60 | S23: 1-16 | T23: 90 | U23: 90 | V23: 12 | W23: Tod | X23: 2-5 | Y23: 3 | Z23: 12
A24: Goliath-Vogelspinne | B24: UD | C24: 0 | I24: X | N24: X | Q24: 23-29 | R24: 50-84 | S24: 1-3 | T24: 15 | U24: 15 | V24: 3-6 | W24: Tod | X24: 1-2 | Y24: 2 | Z24: 10
A25: Großes Wandelndes Blatt | B25: UD | C25: 6 | E25: X | N25: X | Q25: 22-30 | R25: 40-60 | S25: 1-8 | T25: 1.5 | U25: 1.5 | V25: 8 | W25: Tod | X25: 2-7 | Y25: 0 | Z25: Nur 1 Paarung
A26: Grüner Inselleguan | B26: AB | C26: 0 | I26: X | N26: X | Q26: 26-31 | R26: 50-60 | S26: 1-2 | T26: 14 | U26: 14 | V26: ♂: 5 Jahr(e) ♀: 3 Jahr(e) | W26: Tod | X26: 1 | Y26: 3 | Z26: 9
A27: Grüner Leguan | B27: NG | C27: 0 | I27: X | L27: X | N27: X | Q27: 26-31 | R27: 50-60 | S27: 1-2 | T27: 14 | U27: 14 | V27: ♂: 3-4 Jahr(e) ♀: 3-5 Jahr(e) | W27: Tod | X27: 1 | Y27: 4 | Z27: 8
A28: Haariger Wüstenskorpion | B28: UD | C28: 0 | G28: X | P28: X | Q28: 25-37 | R28: 20-35 | S28: 1-6 | T28: 17 | U28: 17 | V28: 4 | W28: Tod | X28: 2-7 | Y28: 9 | Z28: 3
A29: Heiliger Pillendreher | B29: UD | C29: 7 | D29: X | E29: X | F29: X | P29: X | Q29: 20-35 | R29: 40-60 | S29: 1-25 | T29: 5 | U29: 5 | V29: 6 | W29: Tod | X29: 1-3 | Y29: 1 | Z29: 11
A30: Indischer Riesenskorpion | B30: UD | C30: 0 | E30: X | N30: X | Q30: 21-30 | R30: 65-85 | S30: 1-6 | T30: 7 | U30: 7 | V30: 1-3 | W30: Tod | X30: 2-7 | Y30: 9 | Z30: 3
A31: Lehmanns Pfeilgiftfrosch | B31: AB | C31: 0 | I31: X | N31: X | Q31: 26-31 | R31: 80-90 | S31: 1-6 | T31: 10 | U31: 10 | V31: 1 | W31: Tod | X31: 3-6 | Y31: 1 | Z31: 11
A32: Mexikanische Rotknie-Vogelspinne | B32: G | C32: 0 | I32: X | K32: X | N32: X | P32: X | Q32: 23-29 | R32: 50-84 | S32: 1-5 | T32: 20 | U32: 20 | V32: ♂: 4 Jahr(e) ♀: 6-7 Jahr(e) | W32: Tod | X32: 1-3 | Y32: 3 | Z32: 9
A33: Monarchfalter | B33: SG | C33: 13 | E33: X | G33: X | H33: X | I33: X | K33: X | L33: X | N33: X | Q33: 21-30 | R33: - | S33: 1-90 | T33: 9 | U33: 9 | V33: 1 | W33: Tod | X33: 3-6 | Y33: 0 | Z33: Nur 1 Paarung
A34: Nilflughund | B34: NG | C34: 12 | D34: X | E34: X | L34: X | N34: X | P34: X | Q34: 21-32 | R34: - | S34: 5-35 | T34: 17 | U34: 17 | V34: 15 | W34: Tod | X34: 1 | Y34: 4 | Z34: 8
A35: Nordamerikanischer Ochsenfrosch | B35: NG | C35: 8 | G35: X | J35: X | K35: X | Q35: 23-29 | R35: 60-80 | S35: 1-4 | T35: 8 | U35: 8 | V35: 4 | W35: Tod | X35: 1-2 | Y35: 3 | Z35: 9
A36: Östliche Braunschlange | B36: NG | C36: 0 | H36: X | K36: X | L36: X | P36: X | Q36: 23-29 | R36: 60-85 | S36: 1-5 | T36: 11 | U36: 11 | V36: 31 | W36: Tod | X36: 2-3 | Y36: 2 | Z36: 9
A37: Puffotter | B37: NG | C37: 0 | D37: X | E37: X | L37: X | Q37: 23-31 | R37: 60-80 | S37: 1-5 | T37: 14 | U37: 14 | V37: 2 | W37: Tod | X37: 1-3 | Y37: 6 | Z37: 6
A38: Riesenbockkäfer | B38: UD | C38: 0 | I38: X | N38: X | Q38: 23-36 | R38: 40-60 | S38: 1-7 | T38: 1 | U38: 1 | V38: Unbekannt | W38: Tod | X38: 2-5 | Y38: 1 | Z38: Nur 1 Paarung
A39: Rotaugenlaubfrosch | B39: NG | C39: 3 | G39: X | I39: X | N39: X | Q39: 26-31 | R39: 80-90 | S39: 1-5 | T39: 5 | U39: 5 | V39: 1 | W39: Tod | X39: 1-4 | Y39: 0 | Z39: 12
A40: Schrecklicher Pfeilgiftfrosch | B40: SG | C40: 0 | I40: X | N40: X | Q40: 26-31 | R40: 80-90 | S40: 4-7 | T40: 12 | U40: 12 | V40: 12-18 | W40: Tod | X40: 1-4 | Y40: 0 | Z40: 6
A41: Schwalbenschwanz | B41: NG | C41: 13 | E41: X | F41: X | G41: X | K41: X | L41: X | M41: X | O41: X | Q41: 18-24 | R41: - | S41: 1-90 | T41: 9 | U41: 9 | V41: 1,5 | W41: Tod | X41: 3-6 | Y41: 0 | Z41: Nur 1 Paarung
...

Sheet Min|Max Anf. + Berechner
A1: GEHEGEANFORDERUNGEN
A2: Tierart | B2: Wert für 2 Tiere | F2: Wert, um den es sich pro weiterem Tier erhöht | J2: Gehegeanforderungen bei minimalen Bedingungen | N2: Gehegeanforderungen bei maximalen Bedingungen | S2: Berechnung
B4: Gehegegröße | C4: Kletterfläche | D4: Wasserfläche | E4: Tiefwasser | F4: Gehegegröße | G4: Kletterfläche | H4: Wasserfläche | I4: Tiefwasser | J4: Gehegegröße | K4: Kletterfläche | L4: Wasserfläche | M4: Tiefwasser | N4: Gehegegröße | O4: Kletterfläche | P4: Wasserfläche | Q4: Tiefwasser | S4: Gewünschte Tieranzahl | T4: Gehegegröße | U4: Kletterfläche | V4: Wasserfläche | W4: Tiefwasser
A5: ='Wikia | Gehege'!A5 -> Afrikanischer Leopard | B5: 815 | C5: 60 | D5: 0 | E5: 0 | F5: =IFERROR(B5-VLOOKUP($A5,'Wikia | Gehege'!$A:$AL,17,FALSE),0) -> 110 | G5: =IFERROR(C5-VLOOKUP($A5,'Wikia | Gehege'!$A:$AL,18,FALSE),0) -> 15 | H5: =IFERROR(D5-VLOOKUP($A5,'Wikia | Gehege'!$A:$AL,19,FALSE),0) -> 0 | I5: =IFERROR(E5-VLOOKUP($A5,'Wikia | Gehege'!$A:$AL,20,FALSE),0) -> 0 | J5: =IFERROR(IF(VLOOKUP($A5,'Wikia | Gehege'!$A:$AL,26,FALSE)=1,VLOOKUP($A5,'Wikia | Gehege'!$A:$AL,17,FALSE),VLOOKUP($A5,'Wikia | Gehege'!$A:$AL,17,FALSE)+VLOOKUP($A5,'Wikia | Gehege'!$A:$AL,26,FALSE)*($F5)-1*$F5),0) -> 705 | K5: =IFERROR(IF(VLOOKUP($A5,'Wikia | Gehege'!$A:$AL,26,FALSE)=1,VLOOKUP($A5,'Wikia | Gehege'!$A:$AL,18,FALSE),VLOOKUP($A5,'Wikia | Gehege'!$A:$AL,18,FALSE)+VLOOKUP($A5,'Wikia | Gehege'!$A:$AL,26,FALSE)*($G5)-1*$G5),0) -> 45 | L5: =IFERROR(IF(VLOOKUP($A5,'Wikia | Gehege'!$A:$AL,26,FALSE)=1,VLOOKUP($A5,'Wikia | Gehege'!$A:$AL,19,FALSE),VLOOKUP($A5,'Wikia | Gehege'!$A:$AL,19,FALSE)+VLOOKUP($A5,'Wikia | Gehege'!$A:$AL,26,FALSE)*($H5)-1*$H5),0) -> 0 | M5: =IFERROR(IF(VLOOKUP($A5,'Wikia | Gehege'!$A:$AL,26,FALSE)=1,VLOOKUP($A5,'Wikia | Gehege'!$A:$AL,20,FALSE),VLOOKUP($A5,'Wikia | Gehege'!$A:$AL,20,FALSE)+VLOOKUP($A5,'Wikia | Gehege'!$A:$AL,26,FALSE)*($I5)-1*$I5),0) -> 0 | N5: =IFERROR(IF(VLOOKUP($A5,'Wikia | Gehege'!$A:$AL,27,FALSE)=1,VLOOKUP($A5,'Wikia | Gehege'!$A:$AL,17,FALSE),VLOOKUP($A5,'Wikia | Gehege'!$A:$AL,17,FALSE)+VLOOKUP($A5,'Wikia | Gehege'!$A:$AL,27,FALSE)*($F5)-1*$F5),0) -> 815 | O5: =IFERROR(IF(VLOOKUP($A5,'Wikia | Gehege'!$A:$AL,27,FALSE)=1,VLOOKUP($A5,'Wikia | Gehege'!$A:$AL,18,FALSE),VLOOKUP($A5,'Wikia | Gehege'!$A:$AL,18,FALSE)+VLOOKUP($A5,'Wikia | Gehege'!$A:$AL,27,FALSE)*($G5)-1*$G5),0) -> 60 | P5: =IFERROR(IF(VLOOKUP($A5,'Wikia | Gehege'!$A:$AL,27,FALSE)=1,VLOOKUP($A5,'Wikia | Gehege'!$A:$AL,19,FALSE),VLOOKUP($A5,'Wikia | Gehege'!$A:$AL,19,FALSE)+VLOOKUP($A5,'Wikia | Gehege'!$A:$AL,27,FALSE)*($H5)-1*$H5),0) -> 0 | Q5: =IFERROR(IF(VLOOKUP($A5,'Wikia | Gehege'!$A:$AL,27,FALSE)=1,VLOOKUP($A5,'Wikia | Gehege'!$A:$AL,20,FALSE),VLOOKUP($A5,'Wikia | Gehege'!$A:$AL,20,FALSE)+VLOOKUP($A5,'Wikia | Gehege'!$A:$AL,27,FALSE)*($I5)-1*$I5),0) -> 0 | T5: =IFERROR(VLOOKUP($A5,'Wikia | Gehege'!$A:$AL,17,FALSE)+(($S5-1)*$F5),0) -> 595 | U5: =IFERROR(VLOOKUP($A5,'Wikia | Gehege'!$A:$AL,18,FALSE)+(($S5-1)*$G5),0) -> 30 | V5: =IFERROR(VLOOKUP($A5,'Wikia | Gehege'!$A:$AL,19,FALSE)+(($S5-1)*$H5),0) -> 0 | W5: =IFERROR(VLOOKUP($A5,'Wikia | Gehege'!$A:$AL,20,FALSE)+(($S5-1)*$I5),0) -> 0
A6: ='Wikia | Gehege'!A6 -> Afrikanischer Steppenelefant | B6: 2818 | C6: 0 | D6: 222 | E6: 0 | F6: =IFERROR(B6-VLOOKUP($A6,'Wikia | Gehege'!$A:$AL,17,FALSE),0) -> 667 | G6: =IFERROR(C6-VLOOKUP($A6,'Wikia | Gehege'!$A:$AL,18,FALSE),0) -> 0 | H6: =IFERROR(D6-VLOOKUP($A6,'Wikia | Gehege'!$A:$AL,19,FALSE),0) -> 74 | I6: =IFERROR(E6-VLOOKUP($A6,'Wikia | Gehege'!$A:$AL,20,FALSE),0) -> 0 | J6: =IFERROR(IF(VLOOKUP($A6,'Wikia | Gehege'!$A:$AL,26,FALSE)=1,VLOOKUP($A6,'Wikia | Gehege'!$A:$AL,17,FALSE),VLOOKUP($A6,'Wikia | Gehege'!$A:$AL,17,FALSE)+VLOOKUP($A6,'Wikia | Gehege'!$A:$AL,26,FALSE)*($F6)-1*$F6),0) -> 3485 | K6: =IFERROR(IF(VLOOKUP($A6,'Wikia | Gehege'!$A:$AL,26,FALSE)=1,VLOOKUP($A6,'Wikia | Gehege'!$A:$AL,18,FALSE),VLOOKUP($A6,'Wikia | Gehege'!$A:$AL,18,FALSE)+VLOOKUP($A6,'Wikia | Gehege'!$A:$AL,26,FALSE)*($G6)-1*$G6),0) -> 0 | L6: =IFERROR(IF(VLOOKUP($A6,'Wikia | Gehege'!$A:$AL,26,FALSE)=1,VLOOKUP($A6,'Wikia | Gehege'!$A:$AL,19,FALSE),VLOOKUP($A6,'Wikia | Gehege'!$A:$AL,19,FALSE)+VLOOKUP($A6,'Wikia | Gehege'!$A:$AL,26,FALSE)*($H6)-1*$H6),0) -> 296 | M6: =IFERROR(IF(VLOOKUP($A6,'Wikia | Gehege'!$A:$AL,26,FALSE)=1,VLOOKUP($A6,'Wikia | Gehege'!$A:$AL,20,FALSE),VLOOKUP($A6,'Wikia | Gehege'!$A:$AL,20,FALSE)+VLOOKUP($A6,'Wikia | Gehege'!$A:$AL,26,FALSE)*($I6)-1*$I6),0) -> 0 | N6: =IFERROR(IF(VLOOKUP($A6,'Wikia | Gehege'!$A:$AL,27,FALSE)=1,VLOOKUP($A6,'Wikia | Gehege'!$A:$AL,17,FALSE),VLOOKUP($A6,'Wikia | Gehege'!$A:$AL,17,FALSE)+VLOOKUP($A6,'Wikia | Gehege'!$A:$AL,27,FALSE)*($F6)-1*$F6),0) -> 11489 | O6: =IFERROR(IF(VLOOKUP($A6,'Wikia | Gehege'!$A:$AL,27,FALSE)=1,VLOOKUP($A6,'Wikia | Gehege'!$A:$AL,18,FALSE),VLOOKUP($A6,'Wikia | Gehege'!$A:$AL,18,FALSE)+VLOOKUP($A6,'Wikia | Gehege'!$A:$AL,27,FALSE)*($G6)-1*$G6),0) -> 0 | P6: =IFERROR(IF(VLOOKUP($A6,'Wikia | Gehege'!$A:$AL,27,FALSE)=1,VLOOKUP($A6,'Wikia | Gehege'!$A:$AL,19,FALSE),VLOOKUP($A6,'Wikia | Gehege'!$A:$AL,19,FALSE)+VLOOKUP($A6,'Wikia | Gehege'!$A:$AL,27,FALSE)*($H6)-1*$H6),0) -> 1184 | Q6: =IFERROR(IF(VLOOKUP($A6,'Wikia | Gehege'!$A:$AL,27,FALSE)=1,VLOOKUP($A6,'Wikia | Gehege'!$A:$AL,20,FALSE),VLOOKUP($A6,'Wikia | Gehege'!$A:$AL,20,FALSE)+VLOOKUP($A6,'Wikia | Gehege'!$A:$AL,27,FALSE)*($I6)-1*$I6),0) -> 0 | T6: =IFERROR(VLOOKUP($A6,'Wikia | Gehege'!$A:$AL,17,FALSE)+(($S6-1)*$F6),0) -> 1484 | U6: =IFERROR(VLOOKUP($A6,'Wikia | Gehege'!$A:$AL,18,FALSE)+(($S6-1)*$G6),0) -> 0 | V6: =IFERROR(VLOOKUP($A6,'Wikia | Gehege'!$A:$AL,19,FALSE)+(($S6-1)*$H6),0) -> 74 | W6: =IFERROR(VLOOKUP($A6,'Wikia | Gehege'!$A:$AL,20,FALSE)+(($S6-1)*$I6),0) -> 0
A7: ='Wikia | Gehege'!A7 -> Afrikanischer Strauß | B7: 750 | C7: 0 | D7: 0 | E7: 0 | F7: =IFERROR(B7-VLOOKUP($A7,'Wikia | Gehege'!$A:$AL,17,FALSE),0) -> 75 | G7: =IFERROR(C7-VLOOKUP($A7,'Wikia | Gehege'!$A:$AL,18,FALSE),0) -> 0 | H7: =IFERROR(D7-VLOOKUP($A7,'Wikia | Gehege'!$A:$AL,19,FALSE),0) -> 0 | I7: =IFERROR(E7-VLOOKUP($A7,'Wikia | Gehege'!$A:$AL,20,FALSE),0) -> 0 | J7: =IFERROR(IF(VLOOKUP($A7,'Wikia | Gehege'!$A:$AL,26,FALSE)=1,VLOOKUP($A7,'Wikia | Gehege'!$A:$AL,17,FALSE),VLOOKUP($A7,'Wikia | Gehege'!$A:$AL,17,FALSE)+VLOOKUP($A7,'Wikia | Gehege'!$A:$AL,26,FALSE)*($F7)-1*$F7),0) -> 675 | K7: =IFERROR(IF(VLOOKUP($A7,'Wikia | Gehege'!$A:$AL,26,FALSE)=1,VLOOKUP($A7,'Wikia | Gehege'!$A:$AL,18,FALSE),VLOOKUP($A7,'Wikia | Gehege'!$A:$AL,18,FALSE)+VLOOKUP($A7,'Wikia | Gehege'!$A:$AL,26,FALSE)*($G7)-1*$G7),0) -> 0 | L7: =IFERROR(IF(VLOOKUP($A7,'Wikia | Gehege'!$A:$AL,26,FALSE)=1,VLOOKUP($A7,'Wikia | Gehege'!$A:$AL,19,FALSE),VLOOKUP($A7,'Wikia | Gehege'!$A:$AL,19,FALSE)+VLOOKUP($A7,'Wikia | Gehege'!$A:$AL,26,FALSE)*($H7)-1*$H7),0) -> 0 | M7: =IFERROR(IF(VLOOKUP($A7,'Wikia | Gehege'!$A:$AL,26,FALSE)=1,VLOOKUP($A7,'Wikia | Gehege'!$A:$AL,20,FALSE),VLOOKUP($A7,'Wikia | Gehege'!$A:$AL,20,FALSE)+VLOOKUP($A7,'Wikia | Gehege'!$A:$AL,26,FALSE)*($I7)-1*$I7),0) -> 0 | N7: =IFERROR(IF(VLOOKUP($A7,'Wikia | Gehege'!$A:$AL,27,FALSE)=1,VLOOKUP($A7,'Wikia | Gehege'!$A:$AL,17,FALSE),VLOOKUP($A7,'Wikia | Gehege'!$A:$AL,17,FALSE)+VLOOKUP($A7,'Wikia | Gehege'!$A:$AL,27,FALSE)*($F7)-1*$F7),0) -> 1200 | O7: =IFERROR(IF(VLOOKUP($A7,'Wikia | Gehege'!$A:$AL,27,FALSE)=1,VLOOKUP($A7,'Wikia | Gehege'!$A:$AL,18,FALSE),VLOOKUP($A7,'Wikia | Gehege'!$A:$AL,18,FALSE)+VLOOKUP($A7,'Wikia | Gehege'!$A:$AL,27,FALSE)*($G7)-1*$G7),0) -> 0 | P7: =IFERROR(IF(VLOOKUP($A7,'Wikia | Gehege'!$A:$AL,27,FALSE)=1,VLOOKUP($A7,'Wikia | Gehege'!$A:$AL,19,FALSE),VLOOKUP($A7,'Wikia | Gehege'!$A:$AL,19,FALSE)+VLOOKUP($A7,'Wikia | Gehege'!$A:$AL,27,FALSE)*($H7)-1*$H7),0) -> 0 | Q7: =IFERROR(IF(VLOOKUP($A7,'Wikia | Gehege'!$A:$AL,27,FALSE)=1,VLOOKUP($A7,'Wikia | Gehege'!$A:$AL,20,FALSE),VLOOKUP($A7,'Wikia | Gehege'!$A:$AL,20,FALSE)+VLOOKUP($A7,'Wikia | Gehege'!$A:$AL,27,FALSE)*($I7)-1*$I7),0) -> 0 | T7: =IFERROR(VLOOKUP($A7,'Wikia | Gehege'!$A:$AL,17,FALSE)+(($S7-1)*$F7),0) -> 600 | U7: =IFERROR(VLOOKUP($A7,'Wikia | Gehege'!$A:$AL,18,FALSE)+(($S7-1)*$G7),0) -> 0 | V7: =IFERROR(VLOOKUP($A7,'Wikia | Gehege'!$A:$AL,19,FALSE)+(($S7-1)*$H7),0) -> 0 | W7: =IFERROR(VLOOKUP($A7,'Wikia | Gehege'!$A:$AL,20,FALSE)+(($S7-1)*$I7),0) -> 0
A8: ='Wikia | Gehege'!A8 -> Afrikanischer Wildhund | B8: 1254 | C8: 0 | D8: 0 | E8: 0 | F8: =IFERROR(B8-VLOOKUP($A8,'Wikia | Gehege'!$A:$AL,17,FALSE),0) -> 92 | G8: =IFERROR(C8-VLOOKUP($A8,'Wikia | Gehege'!$A:$AL,18,FALSE),0) -> 0 | H8: =IFERROR(D8-VLOOKUP($A8,'Wikia | Gehege'!$A:$AL,19,FALSE),0) -> 0 | I8: =IFERROR(E8-VLOOKUP($A8,'Wikia | Gehege'!$A:$AL,20,FALSE),0) -> 0 | J8: =IFERROR(IF(VLOOKUP($A8,'Wikia | Gehege'!$A:$AL,26,FALSE)=1,VLOOKUP($A8,'Wikia | Gehege'!$A:$AL,17,FALSE),VLOOKUP($A8,'Wikia | Gehege'!$A:$AL,17,FALSE)+VLOOKUP($A8,'Wikia | Gehege'!$A:$AL,26,FALSE)*($F8)-1*$F8),0) -> 1254 | K8: =IFERROR(IF(VLOOKUP($A8,'Wikia | Gehege'!$A:$AL,26,FALSE)=1,VLOOKUP($A8,'Wikia | Gehege'!$A:$AL,18,FALSE),VLOOKUP($A8,'Wikia | Gehege'!$A:$AL,18,FALSE)+VLOOKUP($A8,'Wikia | Gehege'!$A:$AL,26,FALSE)*($G8)-1*$G8),0) -> 0 | L8: =IFERROR(IF(VLOOKUP($A8,'Wikia | Gehege'!$A:$AL,26,FALSE)=1,VLOOKUP($A8,'Wikia | Gehege'!$A:$AL,19,FALSE),VLOOKUP($A8,'Wikia | Gehege'!$A:$AL,19,FALSE)+VLOOKUP($A8,'Wikia | Gehege'!$A:$AL,26,FALSE)*($H8)-1*$H8),0) -> 0 | M8: =IFERROR(IF(VLOOKUP($A8,'Wikia | Gehege'!$A:$AL,26,FALSE)=1,VLOOKUP($A8,'Wikia | Gehege'!$A:$AL,20,FALSE),VLOOKUP($A8,'Wikia | Gehege'!$A:$AL,20,FALSE)+VLOOKUP($A8,'Wikia | Gehege'!$A:$AL,26,FALSE)*($I8)-1*$I8),0) -> 0 | N8: =IFERROR(IF(VLOOKUP($A8,'Wikia | Gehege'!$A:$AL,27,FALSE)=1,VLOOKUP($A8,'Wikia | Gehege'!$A:$AL,17,FALSE),VLOOKUP($A8,'Wikia | Gehege'!$A:$AL,17,FALSE)+VLOOKUP($A8,'Wikia | Gehege'!$A:$AL,27,FALSE)*($F8)-1*$F8),0) -> 3554 | O8: =IFERROR(IF(VLOOKUP($A8,'Wikia | Gehege'!$A:$AL,27,FALSE)=1,VLOOKUP($A8,'Wikia | Gehege'!$A:$AL,18,FALSE),VLOOKUP($A8,'Wikia | Gehege'!$A:$AL,18,FALSE)+VLOOKUP($A8,'Wikia | Gehege'!$A:$AL,27,FALSE)*($G8)-1*$G8),0) -> 0 | P8: =IFERROR(IF(VLOOKUP($A8,'Wikia | Gehege'!$A:$AL,27,FALSE)=1,VLOOKUP($A8,'Wikia | Gehege'!$A:$AL,19,FALSE),VLOOKUP($A8,'Wikia | Gehege'!$A:$AL,19,FALSE)+VLOOKUP($A8,'Wikia | Gehege'!$A:$AL,27,FALSE)*($H8)-1*$H8),0) -> 0 | Q8: =IFERROR(IF(VLOOKUP($A8,'Wikia | Gehege'!$A:$AL,27,FALSE)=1,VLOOKUP($A8,'Wikia | Gehege'!$A:$AL,20,FALSE),VLOOKUP($A8,'Wikia | Gehege'!$A:$AL,20,FALSE)+VLOOKUP($A8,'Wikia | Gehege'!$A:$AL,27,FALSE)*($I8)-1*$I8),0) -> 0 | T8: =IFERROR(VLOOKUP($A8,'Wikia | Gehege'!$A:$AL,17,FALSE)+(($S8-1)*$F8),0) -> 1070 | U8: =IFERROR(VLOOKUP($A8,'Wikia | Gehege'!$A:$AL,18,FALSE)+(($S8-1)*$G8),0) -> 0 | V8: =IFERROR(VLOOKUP($A8,'Wikia | Gehege'!$A:$AL,19,FALSE)+(($S8-1)*$H8),0) -> 0 | W8: =IFERROR(VLOOKUP($A8,'Wikia | Gehege'!$A:$AL,20,FALSE)+(($S8-1)*$I8),0) -> 0
A9: ='Wikia | Gehege'!A9 -> Aldabra-Riesenschildkröte | B9: 235 | C9: 0 | D9: 0 | E9: 0 | F9: =IFERROR(B9-VLOOKUP($A9,'Wikia | Gehege'!$A:$AL,17,FALSE),0) -> 5 | G9: =IFERROR(C9-VLOOKUP($A9,'Wikia | Gehege'!$A:$AL,18,FALSE),0) -> 0 | H9: =IFERROR(D9-VLOOKUP($A9,'Wikia | Gehege'!$A:$AL,19,FALSE),0) -> 0 | I9: =IFERROR(E9-VLOOKUP($A9,'Wikia | Gehege'!$A:$AL,20,FALSE),0) -> 0 | J9: =IFERROR(IF(VLOOKUP($A9,'Wikia | Gehege'!$A:$AL,26,FALSE)=1,VLOOKUP($A9,'Wikia | Gehege'!$A:$AL,17,FALSE),VLOOKUP($A9,'Wikia | Gehege'!$A:$AL,17,FALSE)+VLOOKUP($A9,'Wikia | Gehege'!$A:$AL,26,FALSE)*($F9)-1*$F9),0) -> 230 | K9: =IFERROR(IF(VLOOKUP($A9,'Wikia | Gehege'!$A:$AL,26,FALSE)=1,VLOOKUP($A9,'Wikia | Gehege'!$A:$AL,18,FALSE),VLOOKUP($A9,'Wikia | Gehege'!$A:$AL,18,FALSE)+VLOOKUP($A9,'Wikia | Gehege'!$A:$AL,26,FALSE)*($G9)-1*$G9),0) -> 0 | L9: =IFERROR(IF(VLOOKUP($A9,'Wikia | Gehege'!$A:$AL,26,FALSE)=1,VLOOKUP($A9,'Wikia | Gehege'!$A:$AL,19,FALSE),VLOOKUP($A9,'Wikia | Gehege'!$A:$AL,19,FALSE)+VLOOKUP($A9,'Wikia | Gehege'!$A:$AL,26,FALSE)*($H9)-1*$H9),0) -> 0 | M9: =IFERROR(IF(VLOOKUP($A9,'Wikia | Gehege'!$A:$AL,26,FALSE)=1,VLOOKUP($A9,'Wikia | Gehege'!$A:$AL,20,FALSE),VLOOKUP($A9,'Wikia | Gehege'!$A:$AL,20,FALSE)+VLOOKUP($A9,'Wikia | Gehege'!$A:$AL,26,FALSE)*($I9)-1*$I9),0) -> 0 | N9: =IFERROR(IF(VLOOKUP($A9,'Wikia | Gehege'!$A:$AL,27,FALSE)=1,VLOOKUP($A9,'Wikia | Gehege'!$A:$AL,17,FALSE),VLOOKUP($A9,'Wikia | Gehege'!$A:$AL,17,FALSE)+VLOOKUP($A9,'Wikia | Gehege'!$A:$AL,27,FALSE)*($F9)-1*$F9),0) -> 245 | O9: =IFERROR(IF(VLOOKUP($A9,'Wikia | Gehege'!$A:$AL,27,FALSE)=1,VLOOKUP($A9,'Wikia | Gehege'!$A:$AL,18,FALSE),VLOOKUP($A9,'Wikia | Gehege'!$A:$AL,18,FALSE)+VLOOKUP($A9,'Wikia | Gehege'!$A:$AL,27,FALSE)*($G9)-1*$G9),0) -> 0 | P9: =IFERROR(IF(VLOOKUP($A9,'Wikia | Gehege'!$A:$AL,27,FALSE)=1,VLOOKUP($A9,'Wikia | Gehege'!$A:$AL,19,FALSE),VLOOKUP($A9,'Wikia | Gehege'!$A:$AL,19,FALSE)+VLOOKUP($A9,'Wikia | Gehege'!$A:$AL,27,FALSE)*($H9)-1*$H9),0) -> 0 | Q9: =IFERROR(IF(VLOOKUP($A9,'Wikia | Gehege'!$A:$AL,27,FALSE)=1,VLOOKUP($A9,'Wikia | Gehege'!$A:$AL,20,FALSE),VLOOKUP($A9,'Wikia | Gehege'!$A:$AL,20,FALSE)+VLOOKUP($A9,'Wikia | Gehege'!$A:$AL,27,FALSE)*($I9)-1*$I9),0) -> 0 | T9: =IFERROR(VLOOKUP($A9,'Wikia | Gehege'!$A:$AL,17,FALSE)+(($S9-1)*$F9),0) -> 225 | U9: =IFERROR(VLOOKUP($A9,'Wikia | Gehege'!$A:$AL,18,FALSE)+(($S9-1)*$G9),0) -> 0 | V9: =IFERROR(VLOOKUP($A9,'Wikia | Gehege'!$A:$AL,19,FALSE)+(($S9-1)*$H9),0) -> 0 | W9: =IFERROR(VLOOKUP($A9,'Wikia | Gehege'!$A:$AL,20,FALSE)+(($S9-1)*$I9),0) -> 0
A10: ='Wikia | Gehege'!A10 -> Alpaka | B10: 360 | C10: 0 | D10: 0 | E10: 0 | F10: =IFERROR(B10-VLOOKUP($A10,'Wikia | Gehege'!$A:$AL,17,FALSE),0) -> 35 | G10: =IFERROR(C10-VLOOKUP($A10,'Wikia | Gehege'!$A:$AL,18,FALSE),0) -> 0 | H10: =IFERROR(D10-VLOOKUP($A10,'Wikia | Gehege'!$A:$AL,19,FALSE),0) -> 0 | I10: =IFERROR(E10-VLOOKUP($A10,'Wikia | Gehege'!$A:$AL,20,FALSE),0) -> 0 | J10: =IFERROR(IF(VLOOKUP($A10,'Wikia | Gehege'!$A:$AL,26,FALSE)=1,VLOOKUP($A10,'Wikia | Gehege'!$A:$AL,17,FALSE),VLOOKUP($A10,'Wikia | Gehege'!$A:$AL,17,FALSE)+VLOOKUP($A10,'Wikia | Gehege'!$A:$AL,26,FALSE)*($F10)-1*$F10),0) -> 395 | K10: =IFERROR(IF(VLOOKUP($A10,'Wikia | Gehege'!$A:$AL,26,FALSE)=1,VLOOKUP($A10,'Wikia | Gehege'!$A:$AL,18,FALSE),VLOOKUP($A10,'Wikia | Gehege'!$A:$AL,18,FALSE)+VLOOKUP($A10,'Wikia | Gehege'!$A:$AL,26,FALSE)*($G10)-1*$G10),0) -> 0 | L10: =IFERROR(IF(VLOOKUP($A10,'Wikia | Gehege'!$A:$AL,26,FALSE)=1,VLOOKUP($A10,'Wikia | Gehege'!$A:$AL,19,FALSE),VLOOKUP($A10,'Wikia | Gehege'!$A:$AL,19,FALSE)+VLOOKUP($A10,'Wikia | Gehege'!$A:$AL,26,FALSE)*($H10)-1*$H10),0) -> 0 | M10: =IFERROR(IF(VLOOKUP($A10,'Wikia | Gehege'!$A:$AL,26,FALSE)=1,VLOOKUP($A10,'Wikia | Gehege'!$A:$AL,20,FALSE),VLOOKUP($A10,'Wikia | Gehege'!$A:$AL,20,FALSE)+VLOOKUP($A10,'Wikia | Gehege'!$A:$AL,26,FALSE)*($I10)-1*$I10),0) -> 0 | N10: =IFERROR(IF(VLOOKUP($A10,'Wikia | Gehege'!$A:$AL,27,FALSE)=1,VLOOKUP($A10,'Wikia | Gehege'!$A:$AL,17,FALSE),VLOOKUP($A10,'Wikia | Gehege'!$A:$AL,17,FALSE)+VLOOKUP($A10,'Wikia | Gehege'!$A:$AL,27,FALSE)*($F10)-1*$F10),0) -> 1690 | O10: =IFERROR(IF(VLOOKUP($A10,'Wikia | Gehege'!$A:$AL,27,FALSE)=1,VLOOKUP($A10,'Wikia | Gehege'!$A:$AL,18,FALSE),VLOOKUP($A10,'Wikia | Gehege'!$A:$AL,18,FALSE)+VLOOKUP($A10,'Wikia | Gehege'!$A:$AL,27,FALSE)*($G10)-1*$G10),0) -> 0 | P10: =IFERROR(IF(VLOOKUP($A10,'Wikia | Gehege'!$A:$AL,27,FALSE)=1,VLOOKUP($A10,'Wikia | Gehege'!$A:$AL,19,FALSE),VLOOKUP($A10,'Wikia | Gehege'!$A:$AL,19,FALSE)+VLOOKUP($A10,'Wikia | Gehege'!$A:$AL,27,FALSE)*($H10)-1*$H10),0) -> 0 | Q10: =IFERROR(IF(VLOOKUP($A10,'Wikia | Gehege'!$A:$AL,27,FALSE)=1,VLOOKUP($A10,'Wikia | Gehege'!$A:$AL,20,FALSE),VLOOKUP($A10,'Wikia | Gehege'!$A:$AL,20,FALSE)+VLOOKUP($A10,'Wikia | Gehege'!$A:$AL,27,FALSE)*($I10)-1*$I10),0) -> 0 | T10: =IFERROR(VLOOKUP($A10,'Wikia | Gehege'!$A:$AL,17,FALSE)+(($S10-1)*$F10),0) -> 290 | U10: =IFERROR(VLOOKUP($A10,'Wikia | Gehege'!$A:$AL,18,FALSE)+(($S10-1)*$G10),0) -> 0 | V10: =IFERROR(VLOOKUP($A10,'Wikia | Gehege'!$A:$AL,19,FALSE)+(($S10-1)*$H10),0) -> 0 | W10: =IFERROR(VLOOKUP($A10,'Wikia | Gehege'!$A:$AL,20,FALSE)+(($S10-1)*$I10),0) -> 0
A11: ='Wikia | Gehege'!A11 -> Alpensteinbock | B11: 450 | C11: 0 | D11: 0 | E11: 0 | F11: =IFERROR(B11-VLOOKUP($A11,'Wikia | Gehege'!$A:$AL,17,FALSE),0) -> 60 | G11: =IFERROR(C11-VLOOKUP($A11,'Wikia | Gehege'!$A:$AL,18,FALSE),0) -> 0 | H11: =IFERROR(D11-VLOOKUP($A11,'Wikia | Gehege'!$A:$AL,19,FALSE),0) -> 0 | I11: =IFERROR(E11-VLOOKUP($A11,'Wikia | Gehege'!$A:$AL,20,FALSE),0) -> 0 | J11: =IFERROR(IF(VLOOKUP($A11,'Wikia | Gehege'!$A:$AL,26,FALSE)=1,VLOOKUP($A11,'Wikia | Gehege'!$A:$AL,17,FALSE),VLOOKUP($A11,'Wikia | Gehege'!$A:$AL,17,FALSE)+VLOOKUP($A11,'Wikia | Gehege'!$A:$AL,26,FALSE)*($F11)-1*$F11),0) -> 450 | K11: =IFERROR(IF(VLOOKUP($A11,'Wikia | Gehege'!$A:$AL,26,FALSE)=1,VLOOKUP($A11,'Wikia | Gehege'!$A:$AL,18,FALSE),VLOOKUP($A11,'Wikia | Gehege'!$A:$AL,18,FALSE)+VLOOKUP($A11,'Wikia | Gehege'!$A:$AL,26,FALSE)*($G11)-1*$G11),0) -> 0 | L11: =IFERROR(IF(VLOOKUP($A11,'Wikia | Gehege'!$A:$AL,26,FALSE)=1,VLOOKUP($A11,'Wikia | Gehege'!$A:$AL,19,FALSE),VLOOKUP($A11,'Wikia | Gehege'!$A:$AL,19,FALSE)+VLOOKUP($A11,'Wikia | Gehege'!$A:$AL,26,FALSE)*($H11)-1*$H11),0) -> 0 | M11: =IFERROR(IF(VLOOKUP($A11,'Wikia | Gehege'!$A:$AL,26,FALSE)=1,VLOOKUP($A11,'Wikia | Gehege'!$A:$AL,20,FALSE),VLOOKUP($A11,'Wikia | Gehege'!$A:$AL,20,FALSE)+VLOOKUP($A11,'Wikia | Gehege'!$A:$AL,26,FALSE)*($I11)-1*$I11),0) -> 0 | N11: =IFERROR(IF(VLOOKUP($A11,'Wikia | Gehege'!$A:$AL,27,FALSE)=1,VLOOKUP($A11,'Wikia | Gehege'!$A:$AL,17,FALSE),VLOOKUP($A11,'Wikia | Gehege'!$A:$AL,17,FALSE)+VLOOKUP($A11,'Wikia | Gehege'!$A:$AL,27,FALSE)*($F11)-1*$F11),0) -> 1530 | O11: =IFERROR(IF(VLOOKUP($A11,'Wikia | Gehege'!$A:$AL,27,FALSE)=1,VLOOKUP($A11,'Wikia | Gehege'!$A:$AL,18,FALSE),VLOOKUP($A11,'Wikia | Gehege'!$A:$AL,18,FALSE)+VLOOKUP($A11,'Wikia | Gehege'!$A:$AL,27,FALSE)*($G11)-1*$G11),0) -> 0 | P11: =IFERROR(IF(VLOOKUP($A11,'Wikia | Gehege'!$A:$AL,27,FALSE)=1,VLOOKUP($A11,'Wikia | Gehege'!$A:$AL,19,FALSE),VLOOKUP($A11,'Wikia | Gehege'!$A:$AL,19,FALSE)+VLOOKUP($A11,'Wikia | Gehege'!$A:$AL,27,FALSE)*($H11)-1*$H11),0) -> 0 | Q11: =IFERROR(IF(VLOOKUP($A11,'Wikia | Gehege'!$A:$AL,27,FALSE)=1,VLOOKUP($A11,'Wikia | Gehege'!$A:$AL,20,FALSE),VLOOKUP($A11,'Wikia | Gehege'!$A:$AL,20,FALSE)+VLOOKUP($A11,'Wikia | Gehege'!$A:$AL,27,FALSE)*($I11)-1*$I11),0) -> 0 | T11: =IFERROR(VLOOKUP($A11,'Wikia | Gehege'!$A:$AL,17,FALSE)+(($S11-1)*$F11),0) -> 330 | U11: =IFERROR(VLOOKUP($A11,'Wikia | Gehege'!$A:$AL,18,FALSE)+(($S11-1)*$G11),0) -> 0 | V11: =IFERROR(VLOOKUP($A11,'Wikia | Gehege'!$A:$AL,19,FALSE)+(($S11-1)*$H11),0) -> 0 | W11: =IFERROR(VLOOKUP($A11,'Wikia | Gehege'!$A:$AL,20,FALSE)+(($S11-1)*$I11),0) -> 0
A12: ='Wikia | Gehege'!A12 -> Amerikanischer Standard-Esel | B12: 650 | C12: 0 | D12: 0 | E12: 0 | F12: =IFERROR(B12-VLOOKUP($A12,'Wikia | Gehege'!$A:$AL,17,FALSE),0) -> 150 | G12: =IFERROR(C12-VLOOKUP($A12,'Wikia | Gehege'!$A:$AL,18,FALSE),0) -> 0 | H12: =IFERROR(D12-VLOOKUP($A12,'Wikia | Gehege'!$A:$AL,19,FALSE),0) -> 0 | I12: =IFERROR(E12-VLOOKUP($A12,'Wikia | Gehege'!$A:$AL,20,FALSE),0) -> 0 | J12: =IFERROR(IF(VLOOKUP($A12,'Wikia | Gehege'!$A:$AL,26,FALSE)=1,VLOOKUP($A12,'Wikia | Gehege'!$A:$AL,17,FALSE),VLOOKUP($A12,'Wikia | Gehege'!$A:$AL,17,FALSE)+VLOOKUP($A12,'Wikia | Gehege'!$A:$AL,26,FALSE)*($F12)-1*$F12),0) -> 500 | K12: =IFERROR(IF(VLOOKUP($A12,'Wikia | Gehege'!$A:$AL,26,FALSE)=1,VLOOKUP($A12,'Wikia | Gehege'!$A:$AL,18,FALSE),VLOOKUP($A12,'Wikia | Gehege'!$A:$AL,18,FALSE)+VLOOKUP($A12,'Wikia | Gehege'!$A:$AL,26,FALSE)*($G12)-1*$G12),0) -> 0 | L12: =IFERROR(IF(VLOOKUP($A12,'Wikia | Gehege'!$A:$AL,26,FALSE)=1,VLOOKUP($A12,'Wikia | Gehege'!$A:$AL,19,FALSE),VLOOKUP($A12,'Wikia | Gehege'!$A:$AL,19,FALSE)+VLOOKUP($A12,'Wikia | Gehege'!$A:$AL,26,FALSE)*($H12)-1*$H12),0) -> 0 | M12: =IFERROR(IF(VLOOKUP($A12,'Wikia | Gehege'!$A:$AL,26,FALSE)=1,VLOOKUP($A12,'Wikia | Gehege'!$A:$AL,20,FALSE),VLOOKUP($A12,'Wikia | Gehege'!$A:$AL,20,FALSE)+VLOOKUP($A12,'Wikia | Gehege'!$A:$AL,26,FALSE)*($I12)-1*$I12),0) -> 0 | N12: =IFERROR(IF(VLOOKUP($A12,'Wikia | Gehege'!$A:$AL,27,FALSE)=1,VLOOKUP($A12,'Wikia | Gehege'!$A:$AL,17,FALSE),VLOOKUP($A12,'Wikia | Gehege'!$A:$AL,17,FALSE)+VLOOKUP($A12,'Wikia | Gehege'!$A:$AL,27,FALSE)*($F12)-1*$F12),0) -> 1250 | O12: =IFERROR(IF(VLOOKUP($A12,'Wikia | Gehege'!$A:$AL,27,FALSE)=1,VLOOKUP($A12,'Wikia | Gehege'!$A:$AL,18,FALSE),VLOOKUP($A12,'Wikia | Gehege'!$A:$AL,18,FALSE)+VLOOKUP($A12,'Wikia | Gehege'!$A:$AL,27,FALSE)*($G12)-1*$G12),0) -> 0 | P12: =IFERROR(IF(VLOOKUP($A12,'Wikia | Gehege'!$A:$AL,27,FALSE)=1,VLOOKUP($A12,'Wikia | Gehege'!$A:$AL,19,FALSE),VLOOKUP($A12,'Wikia | Gehege'!$A:$AL,19,FALSE)+VLOOKUP($A12,'Wikia | Gehege'!$A:$AL,27,FALSE)*($H12)-1*$H12),0) -> 0 | Q12: =IFERROR(IF(VLOOKUP($A12,'Wikia | Gehege'!$A:$AL,27,FALSE)=1,VLOOKUP($A12,'Wikia | Gehege'!$A:$AL,20,FALSE),VLOOKUP($A12,'Wikia | Gehege'!$A:$AL,20,FALSE)+VLOOKUP($A12,'Wikia | Gehege'!$A:$AL,27,FALSE)*($I12)-1*$I12),0) -> 0 | T12: =IFERROR(VLOOKUP($A12,'Wikia | Gehege'!$A:$AL,17,FALSE)+(($S12-1)*$F12),0) -> 350 | U12: =IFERROR(VLOOKUP($A12,'Wikia | Gehege'!$A:$AL,18,FALSE)+(($S12-1)*$G12),0) -> 0 | V12: =IFERROR(VLOOKUP($A12,'Wikia | Gehege'!$A:$AL,19,FALSE)+(($S12-1)*$H12),0) -> 0 | W12: =IFERROR(VLOOKUP($A12,'Wikia | Gehege'!$A:$AL,20,FALSE)+(($S12-1)*$I12),0) -> 0
A13: ='Wikia | Gehege'!A13 -> Amerikanischer Biber | B13: 525 | C13: 0 | D13: 367 | E13: 90 | F13: =IFERROR(B13-VLOOKUP($A13,'Wikia | Gehege'!$A:$AL,17,FALSE),0) -> 45 | G13: =IFERROR(C13-VLOOKUP($A13,'Wikia | Gehege'!$A:$AL,18,FALSE),0) -> 0 | H13: =IFERROR(D13-VLOOKUP($A13,'Wikia | Gehege'!$A:$AL,19,FALSE),0) -> 32 | I13: =IFERROR(E13-VLOOKUP($A13,'Wikia | Gehege'!$A:$AL,20,FALSE),0) -> 25 | J13: =IFERROR(IF(VLOOKUP($A13,'Wikia | Gehege'!$A:$AL,26,FALSE)=1,VLOOKUP($A13,'Wikia | Gehege'!$A:$AL,17,FALSE),VLOOKUP($A13,'Wikia | Gehege'!$A:$AL,17,FALSE)+VLOOKUP($A13,'Wikia | Gehege'!$A:$AL,26,FALSE)*($F13)-1*$F13),0) -> 525 | K13: =IFERROR(IF(VLOOKUP($A13,'Wikia | Gehege'!$A:$AL,26,FALSE)=1,VLOOKUP($A13,'Wikia | Gehege'!$A:$AL,18,FALSE),VLOOKUP($A13,'Wikia | Gehege'!$A:$AL,18,FALSE)+VLOOKUP($A13,'Wikia | Gehege'!$A:$AL,26,FALSE)*($G13)-1*$G13),0) -> 0 | L13: =IFERROR(IF(VLOOKUP($A13,'Wikia | Gehege'!$A:$AL,26,FALSE)=1,VLOOKUP($A13,'Wikia | Gehege'!$A:$AL,19,FALSE),VLOOKUP($A13,'Wikia | Gehege'!$A:$AL,19,FALSE)+VLOOKUP($A13,'Wikia | Gehege'!$A:$AL,26,FALSE)*($H13)-1*$H13),0) -> 367 | M13: =IFERROR(IF(VLOOKUP($A13,'Wikia | Gehege'!$A:$AL,26,FALSE)=1,VLOOKUP($A13,'Wikia | Gehege'!$A:$AL,20,FALSE),VLOOKUP($A13,'Wikia | Gehege'!$A:$AL,20,FALSE)+VLOOKUP($A13,'Wikia | Gehege'!$A:$AL,26,FALSE)*($I13)-1*$I13),0) -> 90 | N13: =IFERROR(IF(VLOOKUP($A13,'Wikia | Gehege'!$A:$AL,27,FALSE)=1,VLOOKUP($A13,'Wikia | Gehege'!$A:$AL,17,FALSE),VLOOKUP($A13,'Wikia | Gehege'!$A:$AL,17,FALSE)+VLOOKUP($A13,'Wikia | Gehege'!$A:$AL,27,FALSE)*($F13)-1*$F13),0) -> 795 | O13: =IFERROR(IF(VLOOKUP($A13,'Wikia | Gehege'!$A:$AL,27,FALSE)=1,VLOOKUP($A13,'Wikia | Gehege'!$A:$AL,18,FALSE),VLOOKUP($A13,'Wikia | Gehege'!$A:$AL,18,FALSE)+VLOOKUP($A13,'Wikia | Gehege'!$A:$AL,27,FALSE)*($G13)-1*$G13),0) -> 0 | P13: =IFERROR(IF(VLOOKUP($A13,'Wikia | Gehege'!$A:$AL,27,FALSE)=1,VLOOKUP($A13,'Wikia | Gehege'!$A:$AL,19,FALSE),VLOOKUP($A13,'Wikia | Gehege'!$A:$AL,19,FALSE)+VLOOKUP($A13,'Wikia | Gehege'!$A:$AL,27,FALSE)*($H13)-1*$H13),0) -> 559 | Q13: =IFERROR(IF(VLOOKUP($A13,'Wikia | Gehege'!$A:$AL,27,FALSE)=1,VLOOKUP($A13,'Wikia | Gehege'!$A:$AL,20,FALSE),VLOOKUP($A13,'Wikia | Gehege'!$A:$AL,20,FALSE)+VLOOKUP($A13,'Wikia | Gehege'!$A:$AL,27,FALSE)*($I13)-1*$I13),0) -> 240 | T13: =IFERROR(VLOOKUP($A13,'Wikia | Gehege'!$A:$AL,17,FALSE)+(($S13-1)*$F13),0) -> 435 | U13: =IFERROR(VLOOKUP($A13,'Wikia | Gehege'!$A:$AL,18,FALSE)+(($S13-1)*$G13),0) -> 0 | V13: =IFERROR(VLOOKUP($A13,'Wikia | Gehege'!$A:$AL,19,FALSE)+(($S13-1)*$H13),0) -> 303 | W13: =IFERROR(VLOOKUP($A13,'Wikia | Gehege'!$A:$AL,20,FALSE)+(($S13-1)*$I13),0) -> 40
A14: ='Wikia | Gehege'!A14 -> Amerikanischer Bison | B14: 510 | C14: 0 | D14: 0 | E14: 0 | F14: =IFERROR(B14-VLOOKUP($A14,'Wikia | Gehege'!$A:$AL,17,FALSE),0) -> 90 | G14: =IFERROR(C14-VLOOKUP($A14,'Wikia | Gehege'!$A:$AL,18,FALSE),0) -> 0 | H14: =IFERROR(D14-VLOOKUP($A14,'Wikia | Gehege'!$A:$AL,19,FALSE),0) -> 0 | I14: =IFERROR(E14-VLOOKUP($A14,'Wikia | Gehege'!$A:$AL,20,FALSE),0) -> 0 | J14: =IFERROR(IF(VLOOKUP($A14,'Wikia | Gehege'!$A:$AL,26,FALSE)=1,VLOOKUP($A14,'Wikia | Gehege'!$A:$AL,17,FALSE),VLOOKUP($A14,'Wikia | Gehege'!$A:$AL,17,FALSE)+VLOOKUP($A14,'Wikia | Gehege'!$A:$AL,26,FALSE)*($F14)-1*$F14),0) -> 600 | K14: =IFERROR(IF(VLOOKUP($A14,'Wikia | Gehege'!$A:$AL,26,FALSE)=1,VLOOKUP($A14,'Wikia | Gehege'!$A:$AL,18,FALSE),VLOOKUP($A14,'Wikia | Gehege'!$A:$AL,18,FALSE)+VLOOKUP($A14,'Wikia | Gehege'!$A:$AL,26,FALSE)*($G14)-1*$G14),0) -> 0 | L14: =IFERROR(IF(VLOOKUP($A14,'Wikia | Gehege'!$A:$AL,26,FALSE)=1,VLOOKUP($A14,'Wikia | Gehege'!$A:$AL,19,FALSE),VLOOKUP($A14,'Wikia | Gehege'!$A:$AL,19,FALSE)+VLOOKUP($A14,'Wikia | Gehege'!$A:$AL,26,FALSE)*($H14)-1*$H14),0) -> 0 | M14: =IFERROR(IF(VLOOKUP($A14,'Wikia | Gehege'!$A:$AL,26,FALSE)=1,VLOOKUP($A14,'Wikia | Gehege'!$A:$AL,20,FALSE),VLOOKUP($A14,'Wikia | Gehege'!$A:$AL,20,FALSE)+VLOOKUP($A14,'Wikia | Gehege'!$A:$AL,26,FALSE)*($I14)-1*$I14),0) -> 0 | N14: =IFERROR(IF(VLOOKUP($A14,'Wikia | Gehege'!$A:$AL,27,FALSE)=1,VLOOKUP($A14,'Wikia | Gehege'!$A:$AL,17,FALSE),VLOOKUP($A14,'Wikia | Gehege'!$A:$AL,17,FALSE)+VLOOKUP($A14,'Wikia | Gehege'!$A:$AL,27,FALSE)*($F14)-1*$F14),0) -> 1680 | O14: =IFERROR(IF(VLOOKUP($A14,'Wikia | Gehege'!$A:$AL,27,FALSE)=1,VLOOKUP($A14,'Wikia | Gehege'!$A:$AL,18,FALSE),VLOOKUP($A14,'Wikia | Gehege'!$A:$AL,18,FALSE)+VLOOKUP($A14,'Wikia | Gehege'!$A:$AL,27,FALSE)*($G14)-1*$G14),0) -> 0 | P14: =IFERROR(IF(VLOOKUP($A14,'Wikia | Gehege'!$A:$AL,27,FALSE)=1,VLOOKUP($A14,'Wikia | Gehege'!$A:$AL,19,FALSE),VLOOKUP($A14,'Wikia | Gehege'!$A:$AL,19,FALSE)+VLOOKUP($A14,'Wikia | Gehege'!$A:$AL,27,FALSE)*($H14)-1*$H14),0) -> 0 | Q14: =IFERROR(IF(VLOOKUP($A14,'Wikia | Gehege'!$A:$AL,27,FALSE)=1,VLOOKUP($A14,'Wikia | Gehege'!$A:$AL,20,FALSE),VLOOKUP($A14,'Wikia | Gehege'!$A:$AL,20,FALSE)+VLOOKUP($A14,'Wikia | Gehege'!$A:$AL,27,FALSE)*($I14)-1*$I14),0) -> 0 | T14: =IFERROR(VLOOKUP($A14,'Wikia | Gehege'!$A:$AL,17,FALSE)+(($S14-1)*$F14),0) -> 330 | U14: =IFERROR(VLOOKUP($A14,'Wikia | Gehege'!$A:$AL,18,FALSE)+(($S14-1)*$G14),0) -> 0 | V14: =IFERROR(VLOOKUP($A14,'Wikia | Gehege'!$A:$AL,19,FALSE)+(($S14-1)*$H14),0) -> 0 | W14: =IFERROR(VLOOKUP($A14,'Wikia | Gehege'!$A:$AL,20,FALSE)+(($S14-1)*$I14),0) -> 0
A15: ='Wikia | Gehege'!A15 -> Amurleopard | B15: 816 | C15: 59 | D15: 0 | E15: 0 | F15: =IFERROR(B15-VLOOKUP($A15,'Wikia | Gehege'!$A:$AL,17,FALSE),0) -> 111 | G15: =IFERROR(C15-VLOOKUP($A15,'Wikia | Gehege'!$A:$AL,18,FALSE),0) -> 14 | H15: =IFERROR(D15-VLOOKUP($A15,'Wikia | Gehege'!$A:$AL,19,FALSE),0) -> 0 | I15: =IFERROR(E15-VLOOKUP($A15,'Wikia | Gehege'!$A:$AL,20,FALSE),0) -> 0 | J15: =IFERROR(IF(VLOOKUP($A15,'Wikia | Gehege'!$A:$AL,26,FALSE)=1,VLOOKUP($A15,'Wikia | Gehege'!$A:$AL,17,FALSE),VLOOKUP($A15,'Wikia | Gehege'!$A:$AL,17,FALSE)+VLOOKUP($A15,'Wikia | Gehege'!$A:$AL,26,FALSE)*($F15)-1*$F15),0) -> 705 | K15: =IFERROR(IF(VLOOKUP($A15,'Wikia | Gehege'!$A:$AL,26,FALSE)=1,VLOOKUP($A15,'Wikia | Gehege'!$A:$AL,18,FALSE),VLOOKUP($A15,'Wikia | Gehege'!$A:$AL,18,FALSE)+VLOOKUP($A15,'Wikia | Gehege'!$A:$AL,26,FALSE)*($G15)-1*$G15),0) -> 45 | L15: =IFERROR(IF(VLOOKUP($A15,'Wikia | Gehege'!$A:$AL,26,FALSE)=1,VLOOKUP($A15,'Wikia | Gehege'!$A:$AL,19,FALSE),VLOOKUP($A15,'Wikia | Gehege'!$A:$AL,19,FALSE)+VLOOKUP($A15,'Wikia | Gehege'!$A:$AL,26,FALSE)*($H15)-1*$H15),0) -> 0 | M15: =IFERROR(IF(VLOOKUP($A15,'Wikia | Gehege'!$A:$AL,26,FALSE)=1,VLOOKUP($A15,'Wikia | Gehege'!$A:$AL,20,FALSE),VLOOKUP($A15,'Wikia | Gehege'!$A:$AL,20,FALSE)+VLOOKUP($A15,'Wikia | Gehege'!$A:$AL,26,FALSE)*($I15)-1*$I15),0) -> 0 | N15: =IFERROR(IF(VLOOKUP($A15,'Wikia | Gehege'!$A:$AL,27,FALSE)=1,VLOOKUP($A15,'Wikia | Gehege'!$A:$AL,17,FALSE),VLOOKUP($A15,'Wikia | Gehege'!$A:$AL,17,FALSE)+VLOOKUP($A15,'Wikia | Gehege'!$A:$AL,27,FALSE)*($F15)-1*$F15),0) -> 816 | O15: =IFERROR(IF(VLOOKUP($A15,'Wikia | Gehege'!$A:$AL,27,FALSE)=1,VLOOKUP($A15,'Wikia | Gehege'!$A:$AL,18,FALSE),VLOOKUP($A15,'Wikia | Gehege'!$A:$AL,18,FALSE)+VLOOKUP($A15,'Wikia | Gehege'!$A:$AL,27,FALSE)*($G15)-1*$G15),0) -> 59 | P15: =IFERROR(IF(VLOOKUP($A15,'Wikia | Gehege'!$A:$AL,27,FALSE)=1,VLOOKUP($A15,'Wikia | Gehege'!$A:$AL,19,FALSE),VLOOKUP($A15,'Wikia | Gehege'!$A:$AL,19,FALSE)+VLOOKUP($A15,'Wikia | Gehege'!$A:$AL,27,FALSE)*($H15)-1*$H15),0) -> 0 | Q15: =IFERROR(IF(VLOOKUP($A15,'Wikia | Gehege'!$A:$AL,27,FALSE)=1,VLOOKUP($A15,'Wikia | Gehege'!$A:$AL,20,FALSE),VLOOKUP($A15,'Wikia | Gehege'!$A:$AL,20,FALSE)+VLOOKUP($A15,'Wikia | Gehege'!$A:$AL,27,FALSE)*($I15)-1*$I15),0) -> 0 | T15: =IFERROR(VLOOKUP($A15,'Wikia | Gehege'!$A:$AL,17,FALSE)+(($S15-1)*$F15),0) -> 594 | U15: =IFERROR(VLOOKUP($A15,'Wikia | Gehege'!$A:$AL,18,FALSE)+(($S15-1)*$G15),0) -> 31 | V15: =IFERROR(VLOOKUP($A15,'Wikia | Gehege'!$A:$AL,19,FALSE)+(($S15-1)*$H15),0) -> 0 | W15: =IFERROR(VLOOKUP($A15,'Wikia | Gehege'!$A:$AL,20,FALSE)+(($S15-1)*$I15),0) -> 0
A16: ='Wikia | Gehege'!A16 -> Bindenwaran | B16: 310 | C16: 0 | D16: 100 | E16: 0 | F16: =IFERROR(B16-VLOOKUP($A16,'Wikia | Gehege'!$A:$AL,17,FALSE),0) -> 30 | G16: =IFERROR(C16-VLOOKUP($A16,'Wikia | Gehege'!$A:$AL,18,FALSE),0) -> 0 | H16: =IFERROR(D16-VLOOKUP($A16,'Wikia | Gehege'!$A:$AL,19,FALSE),0) -> 25 | I16: =IFERROR(E16-VLOOKUP($A16,'Wikia | Gehege'!$A:$AL,20,FALSE),0) -> 0 | J16: =IFERROR(IF(VLOOKUP($A16,'Wikia | Gehege'!$A:$AL,26,FALSE)=1,VLOOKUP($A16,'Wikia | Gehege'!$A:$AL,17,FALSE),VLOOKUP($A16,'Wikia | Gehege'!$A:$AL,17,FALSE)+VLOOKUP($A16,'Wikia | Gehege'!$A:$AL,26,FALSE)*($F16)-1*$F16),0) -> 280 | K16: =IFERROR(IF(VLOOKUP($A16,'Wikia | Gehege'!$A:$AL,26,FALSE)=1,VLOOKUP($A16,'Wikia | Gehege'!$A:$AL,18,FALSE),VLOOKUP($A16,'Wikia | Gehege'!$A:$AL,18,FALSE)+VLOOKUP($A16,'Wikia | Gehege'!$A:$AL,26,FALSE)*($G16)-1*$G16),0) -> 0 | L16: =IFERROR(IF(VLOOKUP($A16,'Wikia | Gehege'!$A:$AL,26,FALSE)=1,VLOOKUP($A16,'Wikia | Gehege'!$A:$AL,19,FALSE),VLOOKUP($A16,'Wikia | Gehege'!$A:$AL,19,FALSE)+VLOOKUP($A16,'Wikia | Gehege'!$A:$AL,26,FALSE)*($H16)-1*$H16),0) -> 75 | M16: =IFERROR(IF(VLOOKUP($A16,'Wikia | Gehege'!$A:$AL,26,FALSE)=1,VLOOKUP($A16,'Wikia | Gehege'!$A:$AL,20,FALSE),VLOOKUP($A16,'Wikia | Gehege'!$A:$AL,20,FALSE)+VLOOKUP($A16,'Wikia | Gehege'!$A:$AL,26,FALSE)*($I16)-1*$I16),0) -> 0 | N16: =IFERROR(IF(VLOOKUP($A16,'Wikia | Gehege'!$A:$AL,27,FALSE)=1,VLOOKUP($A16,'Wikia | Gehege'!$A:$AL,17,FALSE),VLOOKUP($A16,'Wikia | Gehege'!$A:$AL,17,FALSE)+VLOOKUP($A16,'Wikia | Gehege'!$A:$AL,27,FALSE)*($F16)-1*$F16),0) -> 310 | O16: =IFERROR(IF(VLOOKUP($A16,'Wikia | Gehege'!$A:$AL,27,FALSE)=1,VLOOKUP($A16,'Wikia | Gehege'!$A:$AL,18,FALSE),VLOOKUP($A16,'Wikia | Gehege'!$A:$AL,18,FALSE)+VLOOKUP($A16,'Wikia | Gehege'!$A:$AL,27,FALSE)*($G16)-1*$G16),0) -> 0 | P16: =IFERROR(IF(VLOOKUP($A16,'Wikia | Gehege'!$A:$AL,27,FALSE)=1,VLOOKUP($A16,'Wikia | Gehege'!$A:$AL,19,FALSE),VLOOKUP($A16,'Wikia | Gehege'!$A:$AL,19,FALSE)+VLOOKUP($A16,'Wikia | Gehege'!$A:$AL,27,FALSE)*($H16)-1*$H16),0) -> 100 | Q16: =IFERROR(IF(VLOOKUP($A16,'Wikia | Gehege'!$A:$AL,27,FALSE)=1,VLOOKUP($A16,'Wikia | Gehege'!$A:$AL,20,FALSE),VLOOKUP($A16,'Wikia | Gehege'!$A:$AL,20,FALSE)+VLOOKUP($A16,'Wikia | Gehege'!$A:$AL,27,FALSE)*($I16)-1*$I16),0) -> 0 | T16: =IFERROR(VLOOKUP($A16,'Wikia | Gehege'!$A:$AL,17,FALSE)+(($S16-1)*$F16),0) -> 250 | U16: =IFERROR(VLOOKUP($A16,'Wikia | Gehege'!$A:$AL,18,FALSE)+(($S16-1)*$G16),0) -> 0 | V16: =IFERROR(VLOOKUP($A16,'Wikia | Gehege'!$A:$AL,19,FALSE)+(($S16-1)*$H16),0) -> 50 | W16: =IFERROR(VLOOKUP($A16,'Wikia | Gehege'!$A:$AL,20,FALSE)+(($S16-1)*$I16),0) -> 0
... A98: ='Wikia | Gehege'!A98 -> Polarwolf | B98: 1254 | C98: 0 | D98: 0 | E98: 0 | F98: =IFERROR(B98-VLOOKUP($A98,'Wikia | Gehege'!$A:$AL,17,FALSE),0) -> 92 | G98: =IFERROR(C98-VLOOKUP($A98,'Wikia | Gehege'!$A:$AL,18,FALSE),0) -> 0 | H98: =IFERROR(D98-VLOOKUP($A98,'Wikia | Gehege'!$A:$AL,19,FALSE),0) -> 0 | I98: =IFERROR(E98-VLOOKUP($A98,'Wikia | Gehege'!$A:$AL,20,FALSE),0) -> 0 | J98: =IFERROR(IF(VLOOKUP($A98,'Wikia | Gehege'!$A:$AL,26,FALSE)=1,VLOOKUP($A98,'Wikia | Gehege'!$A:$AL,17,FALSE),VLOOKUP($A98,'Wikia | Gehege'!$A:$AL,17,FALSE)+VLOOKUP($A98,'Wikia | Gehege'!$A:$AL,26,FALSE)*($F98)-1*$F98),0) -> 1254 | K98: =IFERROR(IF(VLOOKUP($A98,'Wikia | Gehege'!$A:$AL,26,FALSE)=1,VLOOKUP($A98,'Wikia | Gehege'!$A:$AL,18,FALSE),VLOOKUP($A98,'Wikia | Gehege'!$A:$AL,18,FALSE)+VLOOKUP($A98,'Wikia | Gehege'!$A:$AL,26,FALSE)*($G98)-1*$G98),0) -> 0 | L98: =IFERROR(IF(VLOOKUP($A98,'Wikia | Gehege'!$A:$AL,26,FALSE)=1,VLOOKUP($A98,'Wikia | Gehege'!$A:$AL,19,FALSE),VLOOKUP($A98,'Wikia | Gehege'!$A:$AL,19,FALSE)+VLOOKUP($A98,'Wikia | Gehege'!$A:$AL,26,FALSE)*($H98)-1*$H98),0) -> 0 | M98: =IFERROR(IF(VLOOKUP($A98,'Wikia | Gehege'!$A:$AL,26,FALSE)=1,VLOOKUP($A98,'Wikia | Gehege'!$A:$AL,20,FALSE),VLOOKUP($A98,'Wikia | Gehege'!$A:$AL,20,FALSE)+VLOOKUP($A98,'Wikia | Gehege'!$A:$AL,26,FALSE)*($I98)-1*$I98),0) -> 0 | N98: =IFERROR(IF(VLOOKUP($A98,'Wikia | Gehege'!$A:$AL,27,FALSE)=1,VLOOKUP($A98,'Wikia | Gehege'!$A:$AL,17,FALSE),VLOOKUP($A98,'Wikia | Gehege'!$A:$AL,17,FALSE)+VLOOKUP($A98,'Wikia | Gehege'!$A:$AL,27,FALSE)*($F98)-1*$F98),0) -> 1806 | O98: =IFERROR(IF(VLOOKUP($A98,'Wikia | Gehege'!$A:$AL,27,FALSE)=1,VLOOKUP($A98,'Wikia | Gehege'!$A:$AL,18,FALSE),VLOOKUP($A98,'Wikia | Gehege'!$A:$AL,18,FALSE)+VLOOKUP($A98,'Wikia | Gehege'!$A:$AL,27,FALSE)*($G98)-1*$G98),0) -> 0 | P98: =IFERROR(IF(VLOOKUP($A98,'Wikia | Gehege'!$A:$AL,27,FALSE)=1,VLOOKUP($A98,'Wikia | Gehege'!$A:$AL,19,FALSE),VLOOKUP($A98,'Wikia | Gehege'!$A:$AL,19,FALSE)+VLOOKUP($A98,'Wikia | Gehege'!$A:$AL,27,FALSE)*($H98)-1*$H98),0) -> 0 | Q98: =IFERROR(IF(VLOOKUP($A98,'Wikia | Gehege'!$A:$AL,27,FALSE)=1,VLOOKUP($A98,'Wikia | Gehege'!$A:$AL,20,FALSE),VLOOKUP($A98,'Wikia | Gehege'!$A:$AL,20,FALSE)+VLOOKUP($A98,'Wikia | Gehege'!$A:$AL,27,FALSE)*($I98)-1*$I98),0) -> 0 | T98: =IFERROR(VLOOKUP($A98,'Wikia | Gehege'!$A:$AL,17,FALSE)+(($S98-1)*$F98),0) -> 1070 | U98: =IFERROR(VLOOKUP($A98,'Wikia | Gehege'!$A:$AL,18,FALSE)+(($S98-1)*$G98),0) -> 0 | V98: =IFERROR(VLOOKUP($A98,'Wikia | Gehege'!$A:$AL,19,FALSE)+(($S98-1)*$H98),0) -> 0 | W98: =IFERROR(VLOOKUP($A98,'Wikia | Gehege'!$A:$AL,20,FALSE)+(($S98-1)*$I98),0) -> 0
A99: ='Wikia | Gehege'!A99 -> Przewalski-Pferd | B99: 747 | C99: 0 | D99: 0 | E99: 0 | F99: =IFERROR(B99-VLOOKUP($A99,'Wikia | Gehege'!$A:$AL,17,FALSE),0) -> 172 | G99: =IFERROR(C99-VLOOKUP($A99,'Wikia | Gehege'!$A:$AL,18,FALSE),0) -> 0 | H99: =IFERROR(D99-VLOOKUP($A99,'Wikia | Gehege'!$A:$AL,19,FALSE),0) -> 0 | I99: =IFERROR(E99-VLOOKUP($A99,'Wikia | Gehege'!$A:$AL,20,FALSE),0) -> 0 | J99: =IFERROR(IF(VLOOKUP($A99,'Wikia | Gehege'!$A:$AL,26,FALSE)=1,VLOOKUP($A99,'Wikia | Gehege'!$A:$AL,17,FALSE),VLOOKUP($A99,'Wikia | Gehege'!$A:$AL,17,FALSE)+VLOOKUP($A99,'Wikia | Gehege'!$A:$AL,26,FALSE)*($F99)-1*$F99),0) -> 919 | K99: =IFERROR(IF(VLOOKUP($A99,'Wikia | Gehege'!$A:$AL,26,FALSE)=1,VLOOKUP($A99,'Wikia | Gehege'!$A:$AL,18,FALSE),VLOOKUP($A99,'Wikia | Gehege'!$A:$AL,18,FALSE)+VLOOKUP($A99,'Wikia | Gehege'!$A:$AL,26,FALSE)*($G99)-1*$G99),0) -> 0 | L99: =IFERROR(IF(VLOOKUP($A99,'Wikia | Gehege'!$A:$AL,26,FALSE)=1,VLOOKUP($A99,'Wikia | Gehege'!$A:$AL,19,FALSE),VLOOKUP($A99,'Wikia | Gehege'!$A:$AL,19,FALSE)+VLOOKUP($A99,'Wikia | Gehege'!$A:$AL,26,FALSE)*($H99)-1*$H99),0) -> 0 | M99: =IFERROR(IF(VLOOKUP($A99,'Wikia | Gehege'!$A:$AL,26,FALSE)=1,VLOOKUP($A99,'Wikia | Gehege'!$A:$AL,20,FALSE),VLOOKUP($A99,'Wikia | Gehege'!$A:$AL,20,FALSE)+VLOOKUP($A99,'Wikia | Gehege'!$A:$AL,26,FALSE)*($I99)-1*$I99),0) -> 0 | N99: =IFERROR(IF(VLOOKUP($A99,'Wikia | Gehege'!$A:$AL,27,FALSE)=1,VLOOKUP($A99,'Wikia | Gehege'!$A:$AL,17,FALSE),VLOOKUP($A99,'Wikia | Gehege'!$A:$AL,17,FALSE)+VLOOKUP($A99,'Wikia | Gehege'!$A:$AL,27,FALSE)*($F99)-1*$F99),0) -> 1779 | O99: =IFERROR(IF(VLOOKUP($A99,'Wikia | Gehege'!$A:$AL,27,FALSE)=1,VLOOKUP($A99,'Wikia | Gehege'!$A:$AL,18,FALSE),VLOOKUP($A99,'Wikia | Gehege'!$A:$AL,18,FALSE)+VLOOKUP($A99,'Wikia | Gehege'!$A:$AL,27,FALSE)*($G99)-1*$G99),0) -> 0 | P99: =IFERROR(IF(VLOOKUP($A99,'Wikia | Gehege'!$A:$AL,27,FALSE)=1,VLOOKUP($A99,'Wikia | Gehege'!$A:$AL,19,FALSE),VLOOKUP($A99,'Wikia | Gehege'!$A:$AL,19,FALSE)+VLOOKUP($A99,'Wikia | Gehege'!$A:$AL,27,FALSE)*($H99)-1*$H99),0) -> 0 | Q99: =IFERROR(IF(VLOOKUP($A99,'Wikia | Gehege'!$A:$AL,27,FALSE)=1,VLOOKUP($A99,'Wikia | Gehege'!$A:$AL,20,FALSE),VLOOKUP($A99,'Wikia | Gehege'!$A:$AL,20,FALSE)+VLOOKUP($A99,'Wikia | Gehege'!$A:$AL,27,FALSE)*($I99)-1*$I99),0) -> 0 | R99: 0 | T99: =IFERROR(VLOOKUP($A99,'Wikia | Gehege'!$A:$AL,17,FALSE)+(($S99-1)*$F99),0) -> 403 | U99: =IFERROR(VLOOKUP($A99,'Wikia | Gehege'!$A:$AL,18,FALSE)+(($S99-1)*$G99),0) -> 0 | V99: =IFERROR(VLOOKUP($A99,'Wikia | Gehege'!$A:$AL,19,FALSE)+(($S99-1)*$H99),0) -> 0 | W99: =IFERROR(VLOOKUP($A99,'Wikia | Gehege'!$A:$AL,20,FALSE)+(($S99-1)*$I99),0) -> 0
A100: ='Wikia | Gehege'!A100 -> Puma | B100: 816 | C100: 0 | D100: 0 | E100: 0 | F100: =IFERROR(B100-VLOOKUP($A100,'Wikia | Gehege'!$A:$AL,17,FALSE),0) -> 111 | G100: =IFERROR(C100-VLOOKUP($A100,'Wikia | Gehege'!$A:$AL,18,FALSE),0) -> 0 | H100: =IFERROR(D100-VLOOKUP($A100,'Wikia | Gehege'!$A:$AL,19,FALSE),0) -> 0 | I100: =IFERROR(E100-VLOOKUP($A100,'Wikia | Gehege'!$A:$AL,20,FALSE),0) -> 0 | J100: =IFERROR(IF(VLOOKUP($A100,'Wikia | Gehege'!$A:$AL,26,FALSE)=1,VLOOKUP($A100,'Wikia | Gehege'!$A:$AL,17,FALSE),VLOOKUP($A100,'Wikia | Gehege'!$A:$AL,17,FALSE)+VLOOKUP($A100,'Wikia | Gehege'!$A:$AL,26,FALSE)*($F100)-1*$F100),0) -> 705 | K100: =IFERROR(IF(VLOOKUP($A100,'Wikia | Gehege'!$A:$AL,26,FALSE)=1,VLOOKUP($A100,'Wikia | Gehege'!$A:$AL,18,FALSE),VLOOKUP($A100,'Wikia | Gehege'!$A:$AL,18,FALSE)+VLOOKUP($A100,'Wikia | Gehege'!$A:$AL,26,FALSE)*($G100)-1*$G100),0) -> 0 | L100: =IFERROR(IF(VLOOKUP($A100,'Wikia | Gehege'!$A:$AL,26,FALSE)=1,VLOOKUP($A100,'Wikia | Gehege'!$A:$AL,19,FALSE),VLOOKUP($A100,'Wikia | Gehege'!$A:$AL,19,FALSE)+VLOOKUP($A100,'Wikia | Gehege'!$A:$AL,26,FALSE)*($H100)-1*$H100),0) -> 0 | M100: =IFERROR(IF(VLOOKUP($A100,'Wikia | Gehege'!$A:$AL,26,FALSE)=1,VLOOKUP($A100,'Wikia | Gehege'!$A:$AL,20,FALSE),VLOOKUP($A100,'Wikia | Gehege'!$A:$AL,20,FALSE)+VLOOKUP($A100,'Wikia | Gehege'!$A:$AL,26,FALSE)*($I100)-1*$I100),0) -> 0 | N100: =IFERROR(IF(VLOOKUP($A100,'Wikia | Gehege'!$A:$AL,27,FALSE)=1,VLOOKUP($A100,'Wikia | Gehege'!$A:$AL,17,FALSE),VLOOKUP($A100,'Wikia | Gehege'!$A:$AL,17,FALSE)+VLOOKUP($A100,'Wikia | Gehege'!$A:$AL,27,FALSE)*($F100)-1*$F100),0) -> 816 | O100: =IFERROR(IF(VLOOKUP($A100,'Wikia | Gehege'!$A:$AL,27,FALSE)=1,VLOOKUP($A100,'Wikia | Gehege'!$A:$AL,18,FALSE),VLOOKUP($A100,'Wikia | Gehege'!$A:$AL,18,FALSE)+VLOOKUP($A100,'Wikia | Gehege'!$A:$AL,27,FALSE)*($G100)-1*$G100),0) -> 0 | P100: =IFERROR(IF(VLOOKUP($A100,'Wikia | Gehege'!$A:$AL,27,FALSE)=1,VLOOKUP($A100,'Wikia | Gehege'!$A:$AL,19,FALSE),VLOOKUP($A100,'Wikia | Gehege'!$A:$AL,19,FALSE)+VLOOKUP($A100,'Wikia | Gehege'!$A:$AL,27,FALSE)*($H100)-1*$H100),0) -> 0 | Q100: =IFERROR(IF(VLOOKUP($A100,'Wikia | Gehege'!$A:$AL,27,FALSE)=1,VLOOKUP($A100,'Wikia | Gehege'!$A:$AL,20,FALSE),VLOOKUP($A100,'Wikia | Gehege'!$A:$AL,20,FALSE)+VLOOKUP($A100,'Wikia | Gehege'!$A:$AL,27,FALSE)*($I100)-1*$I100),0) -> 0 | T100: =IFERROR(VLOOKUP($A100,'Wikia | Gehege'!$A:$AL,17,FALSE)+(($S100-1)*$F100),0) -> 594 | U100: =IFERROR(VLOOKUP($A100,'Wikia | Gehege'!$A:$AL,18,FALSE)+(($S100-1)*$G100),0) -> 0 | V100: =IFERROR(VLOOKUP($A100,'Wikia | Gehege'!$A:$AL,19,FALSE)+(($S100-1)*$H100),0) -> 0 | W100: =IFERROR(VLOOKUP($A100,'Wikia | Gehege'!$A:$AL,20,FALSE)+(($S100-1)*$I100),0) -> 0
